5:return {{["y"] = 0, ["x"] = 0, ["name"] = "default:stone", ["z"] = 16, ["param1"] = 2}, {["y"] = 0, ["x"] = 0, ["name"] = "default:stone", ["z"] = 17, ["param1"] = 2}, {["y"] = 0, ["x"] = 0, ["name"] = "default:stone", ["z"] = 18, ["param1"] = 2}, {["y"] = 0, ["x"] = 0, ["name"] = "default:stone", ["z"] = 19, ["param1"] = 2}, {["y"] = 0, ["x"] = 0, ["name"] = "default:stone", ["z"] = 20, ["param1"] = 2}, {["y"] = 0, ["x"] = 0, ["name"] = "default:stone", ["z"] = 21, ["param1"] = 2}, {["y"] = 0, ["x"] = 0, ["name"] = "default:stone", ["z"] = 22, ["param1"] = 2}, {["y"] = 0, ["x"] = 0, ["name"] = "default:stone", ["z"] = 23, ["param1"] = 2}, {["y"] = 0, ["x"] = 0, ["name"] = "default:stone", ["z"] = 24, ["param1"] = 2}, {["y"] = 0, ["x"] = 0, ["name"] = "default:stone", ["z"] = 25, ["param1"] = 2}, {["y"] = 0, ["x"] = 0, ["name"] = "default:stone", ["z"] = 26, ["param1"] = 2}, {["y"] = 0, ["x"] = 0, ["name"] = "default:stone", ["z"] = 27, ["param1"] = 2}, {["y"] = 0, ["x"] = 0, ["name"] = "default:stone", ["z"] = 28, ["param1"] = 2}, {["y"] = 0, ["x"] = 0, ["name"] = "default:stone", ["z"] = 29, ["param1"] = 2}, {["y"] = 0, ["x"] = 0, ["name"] = "default:stone", ["z"] = 30, ["param1"] = 2}, {["y"] = 0, ["x"] = 0, ["name"] = "default:stone", ["z"] = 31, ["param1"] = 2}, {["y"] = 1, ["x"] = 0, ["name"] = "default:stone", ["z"] = 16, ["param1"] = 2}, {["y"] = 1, ["x"] = 0, ["name"] = "default:stone", ["z"] = 17, ["param1"] = 2}, {["y"] = 1, ["x"] = 0, ["name"] = "default:stone", ["z"] = 18, ["param1"] = 2}, {["y"] = 1, ["x"] = 0, ["name"] = "default:stone", ["z"] = 19, ["param1"] = 2}, {["y"] = 1, ["x"] = 0, ["name"] = "default:stone", ["z"] = 20, ["param1"] = 2}, {["y"] = 1, ["x"] = 0, ["name"] = "default:stone", ["z"] = 21, ["param1"] = 2}, {["y"] = 1, ["x"] = 0, ["name"] = "default:stone", ["z"] = 22, ["param1"] = 2}, {["y"] = 1, ["x"] = 0, ["name"] = "default:stone", ["z"] = 23, ["param1"] = 2}, {["y"] = 1, ["x"] = 0, ["name"] = "default:stone", ["z"] = 24, ["param1"] = 2}, {["y"] = 1, ["x"] = 0, ["name"] = "default:stone", ["z"] = 25, ["param1"] = 2}, {["y"] = 1, ["x"] = 0, ["name"] = "default:stone", ["z"] = 26, ["param1"] = 2}, {["y"] = 1, ["x"] = 0, ["name"] = "default:stone", ["z"] = 27, ["param1"] = 2}, {["y"] = 1, ["x"] = 0, ["name"] = "default:stone", ["z"] = 28, ["param1"] = 2}, {["y"] = 1, ["x"] = 0, ["name"] = "default:stone", ["z"] = 29, ["param1"] = 2}, {["y"] = 1, ["x"] = 0, ["name"] = "default:stone", ["z"] = 30, ["param1"] = 2}, {["y"] = 1, ["x"] = 0, ["name"] = "default:stone", ["z"] = 31, ["param1"] = 2}, {["y"] = 2, ["x"] = 0, ["name"] = "default:stonebrick", ["z"] = 16, ["param2"] = 1, ["param1"] = 4}, {["y"] = 2, ["x"] = 0, ["name"] = "default:stonebrick", ["z"] = 17, ["param2"] = 1, ["param1"] = 4}, {["y"] = 2, ["x"] = 0, ["name"] = "default:stonebrick", ["z"] = 18, ["param2"] = 1, ["param1"] = 4}, {["y"] = 2, ["x"] = 0, ["name"] = "default:stonebrick", ["z"] = 19, ["param2"] = 1, ["param1"] = 4}, {["y"] = 2, ["x"] = 0, ["name"] = "default:stonebrick", ["z"] = 20, ["param2"] = 1, ["param1"] = 4}, {["y"] = 2, ["x"] = 0, ["name"] = "default:stonebrick", ["z"] = 21, ["param2"] = 1, ["param1"] = 4}, {["y"] = 2, ["x"] = 0, ["name"] = "default:stonebrick", ["z"] = 22, ["param2"] = 1, ["param1"] = 4}, {["y"] = 2, ["x"] = 0, ["name"] = "default:stonebrick", ["z"] = 23, ["param2"] = 1, ["param1"] = 4}, {["y"] = 2, ["x"] = 0, ["name"] = "default:stonebrick", ["z"] = 24, ["param2"] = 1, ["param1"] = 4}, {["y"] = 2, ["x"] = 0, ["name"] = "default:stonebrick", ["z"] = 25, ["param2"] = 1, ["param1"] = 4}, {["y"] = 2, ["x"] = 0, ["name"] = "default:stonebrick", ["z"] = 26, ["param2"] = 1, ["param1"] = 4}, {["y"] = 2, ["x"] = 0, ["name"] = "default:stonebrick", ["z"] = 27, ["param2"] = 1, ["param1"] = 4}, {["y"] = 2, ["x"] = 0, ["name"] = "default:stonebrick", ["z"] = 28, ["param2"] = 1, ["param1"] = 4}, {["y"] = 2, ["x"] = 0, ["name"] = "default:stonebrick", ["z"] = 29, ["param2"] = 1, ["param1"] = 4}, {["y"] = 2, ["x"] = 0, ["name"] = "default:stonebrick", ["z"] = 30, ["param2"] = 1, ["param1"] = 4}, {["y"] = 2, ["x"] = 0, ["name"] = "default:stonebrick", ["z"] = 31, ["param2"] = 1, ["param1"] = 4}, {["y"] = 3, ["x"] = 0, ["name"] = "moreblocks:checker_stone_tile", ["z"] = 16, ["param1"] = 46}, {["y"] = 3, ["x"] = 0, ["name"] = "moreblocks:checker_stone_tile", ["z"] = 17, ["param1"] = 46}, {["y"] = 3, ["x"] = 0, ["name"] = "moreblocks:checker_stone_tile", ["z"] = 18, ["param1"] = 46}, {["y"] = 3, ["x"] = 0, ["name"] = "moreblocks:checker_stone_tile", ["z"] = 19, ["param1"] = 46}, {["y"] = 3, ["x"] = 0, ["name"] = "moreblocks:checker_stone_tile", ["z"] = 20, ["param1"] = 46}, {["y"] = 3, ["x"] = 0, ["name"] = "moreblocks:checker_stone_tile", ["z"] = 21, ["param1"] = 46}, {["y"] = 3, ["x"] = 0, ["name"] = "moreblocks:checker_stone_tile", ["z"] = 22, ["param1"] = 46}, {["y"] = 3, ["x"] = 0, ["name"] = "moreblocks:checker_stone_tile", ["z"] = 23, ["param1"] = 46}, {["y"] = 3, ["x"] = 0, ["name"] = "moreblocks:checker_stone_tile", ["z"] = 24, ["param1"] = 46}, {["y"] = 3, ["x"] = 0, ["name"] = "moreblocks:checker_stone_tile", ["z"] = 25, ["param1"] = 46}, {["y"] = 3, ["x"] = 0, ["name"] = "moreblocks:checker_stone_tile", ["z"] = 26, ["param1"] = 46}, {["y"] = 3, ["x"] = 0, ["name"] = "moreblocks:checker_stone_tile", ["z"] = 27, ["param1"] = 46}, {["y"] = 3, ["x"] = 0, ["name"] = "moreblocks:checker_stone_tile", ["z"] = 28, ["param1"] = 46}, {["y"] = 3, ["x"] = 0, ["name"] = "moreblocks:checker_stone_tile", ["z"] = 29, ["param1"] = 46}, {["y"] = 3, ["x"] = 0, ["name"] = "moreblocks:checker_stone_tile", ["z"] = 30, ["param1"] = 46}, {["y"] = 3, ["x"] = 0, ["name"] = "moreblocks:checker_stone_tile", ["z"] = 31, ["param1"] = 46}, {["y"] = 6, ["x"] = 0, ["name"] = "moreblocks:slab_meselamp_1", ["z"] = 16, ["param2"] = 22, ["param1"] = 222}, {["y"] = 6, ["x"] = 0, ["name"] = "moreblocks:slab_meselamp_1", ["z"] = 23, ["param2"] = 23, ["param1"] = 222}, {["y"] = 6, ["x"] = 0, ["name"] = "moreblocks:slab_meselamp_1", ["z"] = 24, ["param2"] = 23, ["param1"] = 222}, {["y"] = 6, ["x"] = 0, ["name"] = "moreblocks:slab_meselamp_1", ["z"] = 31, ["param2"] = 22, ["param1"] = 222}, {["y"] = 7, ["x"] = 0, ["name"] = "moreblocks:coal_stone", ["z"] = 16, ["param1"] = 186}, {["y"] = 7, ["x"] = 0, ["name"] = "moreblocks:coal_stone", ["z"] = 17, ["param1"] = 186}, {["y"] = 7, ["x"] = 0, ["name"] = "moreblocks:coal_stone", ["z"] = 18, ["param1"] = 186}, {["y"] = 7, ["x"] = 0, ["name"] = "moreblocks:coal_stone", ["z"] = 19, ["param1"] = 186}, {["y"] = 7, ["x"] = 0, ["name"] = "moreblocks:coal_stone", ["z"] = 20, ["param1"] = 186}, {["y"] = 7, ["x"] = 0, ["name"] = "moreblocks:coal_stone", ["z"] = 21, ["param1"] = 186}, {["y"] = 7, ["x"] = 0, ["name"] = "moreblocks:coal_stone", ["z"] = 22, ["param1"] = 186}, {["y"] = 7, ["x"] = 0, ["name"] = "moreblocks:coal_stone", ["z"] = 23, ["param1"] = 186}, {["y"] = 7, ["x"] = 0, ["name"] = "moreblocks:coal_stone", ["z"] = 24, ["param1"] = 186}, {["y"] = 7, ["x"] = 0, ["name"] = "moreblocks:coal_stone", ["z"] = 25, ["param1"] = 186}, {["y"] = 7, ["x"] = 0, ["name"] = "moreblocks:coal_stone", ["z"] = 26, ["param1"] = 186}, {["y"] = 7, ["x"] = 0, ["name"] = "moreblocks:coal_stone", ["z"] = 27, ["param1"] = 186}, {["y"] = 7, ["x"] = 0, ["name"] = "moreblocks:coal_stone", ["z"] = 28, ["param1"] = 186}, {["y"] = 7, ["x"] = 0, ["name"] = "moreblocks:coal_stone", ["z"] = 29, ["param1"] = 186}, {["y"] = 7, ["x"] = 0, ["name"] = "moreblocks:coal_stone", ["z"] = 30, ["param1"] = 186}, {["y"] = 7, ["x"] = 0, ["name"] = "moreblocks:coal_stone", ["z"] = 31, ["param1"] = 186}, {["y"] = 8, ["x"] = 0, ["name"] = "moreblocks:checker_stone_tile", ["z"] = 16, ["param1"] = 46}, {["y"] = 8, ["x"] = 0, ["name"] = "moreblocks:checker_stone_tile", ["z"] = 17, ["param1"] = 46}, {["y"] = 8, ["x"] = 0, ["name"] = "moreblocks:checker_stone_tile", ["z"] = 18, ["param1"] = 46}, {["y"] = 8, ["x"] = 0, ["name"] = "moreblocks:checker_stone_tile", ["z"] = 19, ["param1"] = 46}, {["y"] = 8, ["x"] = 0, ["name"] = "moreblocks:checker_stone_tile", ["z"] = 20, ["param1"] = 46}, {["y"] = 8, ["x"] = 0, ["name"] = "moreblocks:checker_stone_tile", ["z"] = 21, ["param1"] = 46}, {["y"] = 8, ["x"] = 0, ["name"] = "moreblocks:checker_stone_tile", ["z"] = 22, ["param1"] = 46}, {["y"] = 8, ["x"] = 0, ["name"] = "moreblocks:checker_stone_tile", ["z"] = 23, ["param1"] = 46}, {["y"] = 8, ["x"] = 0, ["name"] = "moreblocks:checker_stone_tile", ["z"] = 24, ["param1"] = 46}, {["y"] = 8, ["x"] = 0, ["name"] = "moreblocks:checker_stone_tile", ["z"] = 25, ["param1"] = 46}, {["y"] = 8, ["x"] = 0, ["name"] = "moreblocks:checker_stone_tile", ["z"] = 26, ["param1"] = 46}, {["y"] = 8, ["x"] = 0, ["name"] = "moreblocks:checker_stone_tile", ["z"] = 27, ["param1"] = 46}, {["y"] = 8, ["x"] = 0, ["name"] = "moreblocks:checker_stone_tile", ["z"] = 28, ["param1"] = 46}, {["y"] = 8, ["x"] = 0, ["name"] = "moreblocks:checker_stone_tile", ["z"] = 29, ["param1"] = 46}, {["y"] = 8, ["x"] = 0, ["name"] = "moreblocks:checker_stone_tile", ["z"] = 30, ["param1"] = 46}, {["y"] = 8, ["x"] = 0, ["name"] = "moreblocks:checker_stone_tile", ["z"] = 31, ["param1"] = 46}, {["y"] = 14, ["x"] = 0, ["name"] = "moreblocks:slab_meselamp_1", ["z"] = 16, ["param2"] = 22, ["param1"] = 222}, {["y"] = 14, ["x"] = 0, ["name"] = "moreblocks:slab_meselamp_1", ["z"] = 23, ["param2"] = 23, ["param1"] = 222}, {["y"] = 14, ["x"] = 0, ["name"] = "moreblocks:slab_meselamp_1", ["z"] = 24, ["param2"] = 23, ["param1"] = 222}, {["y"] = 14, ["x"] = 0, ["name"] = "moreblocks:slab_meselamp_1", ["z"] = 31, ["param2"] = 22, ["param1"] = 222}, {["y"] = 15, ["x"] = 0, ["name"] = "moreblocks:coal_stone", ["z"] = 16, ["param1"] = 186}, {["y"] = 15, ["x"] = 0, ["name"] = "moreblocks:coal_stone", ["z"] = 17, ["param1"] = 186}, {["y"] = 15, ["x"] = 0, ["name"] = "moreblocks:coal_stone", ["z"] = 18, ["param1"] = 186}, {["y"] = 15, ["x"] = 0, ["name"] = "moreblocks:coal_stone", ["z"] = 19, ["param1"] = 186}, {["y"] = 15, ["x"] = 0, ["name"] = "moreblocks:coal_stone", ["z"] = 20, ["param1"] = 186}, {["y"] = 15, ["x"] = 0, ["name"] = "moreblocks:coal_stone", ["z"] = 21, ["param1"] = 186}, {["y"] = 15, ["x"] = 0, ["name"] = "moreblocks:coal_stone", ["z"] = 22, ["param1"] = 186}, {["y"] = 15, ["x"] = 0, ["name"] = "moreblocks:coal_stone", ["z"] = 23, ["param1"] = 186}, {["y"] = 15, ["x"] = 0, ["name"] = "moreblocks:coal_stone", ["z"] = 24, ["param1"] = 186}, {["y"] = 15, ["x"] = 0, ["name"] = "moreblocks:coal_stone", ["z"] = 25, ["param1"] = 186}, {["y"] = 15, ["x"] = 0, ["name"] = "moreblocks:coal_stone", ["z"] = 26, ["param1"] = 186}, {["y"] = 15, ["x"] = 0, ["name"] = "moreblocks:coal_stone", ["z"] = 27, ["param1"] = 186}, {["y"] = 15, ["x"] = 0, ["name"] = "moreblocks:coal_stone", ["z"] = 28, ["param1"] = 186}, {["y"] = 15, ["x"] = 0, ["name"] = "moreblocks:coal_stone", ["z"] = 29, ["param1"] = 186}, {["y"] = 15, ["x"] = 0, ["name"] = "moreblocks:coal_stone", ["z"] = 30, ["param1"] = 186}, {["y"] = 15, ["x"] = 0, ["name"] = "moreblocks:coal_stone", ["z"] = 31, ["param1"] = 186}, {["y"] = 16, ["x"] = 0, ["name"] = "moreblocks:checker_stone_tile", ["z"] = 16, ["param1"] = 46}, {["y"] = 16, ["x"] = 0, ["name"] = "moreblocks:checker_stone_tile", ["z"] = 17, ["param1"] = 46}, {["y"] = 16, ["x"] = 0, ["name"] = "moreblocks:checker_stone_tile", ["z"] = 18, ["param1"] = 46}, {["y"] = 16, ["x"] = 0, ["name"] = "moreblocks:checker_stone_tile", ["z"] = 19, ["param1"] = 46}, {["y"] = 16, ["x"] = 0, ["name"] = "moreblocks:checker_stone_tile", ["z"] = 20, ["param1"] = 46}, {["y"] = 16, ["x"] = 0, ["name"] = "moreblocks:checker_stone_tile", ["z"] = 21, ["param1"] = 46}, {["y"] = 16, ["x"] = 0, ["name"] = "moreblocks:checker_stone_tile", ["z"] = 22, ["param1"] = 46}, {["y"] = 16, ["x"] = 0, ["name"] = "moreblocks:checker_stone_tile", ["z"] = 23, ["param1"] = 46}, {["y"] = 16, ["x"] = 0, ["name"] = "moreblocks:checker_stone_tile", ["z"] = 24, ["param1"] = 46}, {["y"] = 16, ["x"] = 0, ["name"] = "moreblocks:checker_stone_tile", ["z"] = 25, ["param1"] = 46}, {["y"] = 16, ["x"] = 0, ["name"] = "moreblocks:checker_stone_tile", ["z"] = 26, ["param1"] = 46}, {["y"] = 16, ["x"] = 0, ["name"] = "moreblocks:checker_stone_tile", ["z"] = 27, ["param1"] = 46}, {["y"] = 16, ["x"] = 0, ["name"] = "moreblocks:checker_stone_tile", ["z"] = 28, ["param1"] = 46}, {["y"] = 16, ["x"] = 0, ["name"] = "moreblocks:checker_stone_tile", ["z"] = 29, ["param1"] = 46}, {["y"] = 16, ["x"] = 0, ["name"] = "moreblocks:checker_stone_tile", ["z"] = 30, ["param1"] = 46}, {["y"] = 16, ["x"] = 0, ["name"] = "moreblocks:checker_stone_tile", ["z"] = 31, ["param1"] = 46}, {["y"] = 22, ["x"] = 0, ["name"] = "moreblocks:slab_meselamp_1", ["z"] = 16, ["param2"] = 22, ["param1"] = 222}, {["y"] = 22, ["x"] = 0, ["name"] = "moreblocks:slab_meselamp_1", ["z"] = 23, ["param2"] = 23, ["param1"] = 222}, {["y"] = 22, ["x"] = 0, ["name"] = "moreblocks:slab_meselamp_1", ["z"] = 24, ["param2"] = 23, ["param1"] = 222}, {["y"] = 22, ["x"] = 0, ["name"] = "moreblocks:slab_meselamp_1", ["z"] = 31, ["param2"] = 22, ["param1"] = 222}, {["y"] = 23, ["x"] = 0, ["name"] = "moreblocks:coal_stone", ["z"] = 16, ["param1"] = 186}, {["y"] = 23, ["x"] = 0, ["name"] = "moreblocks:coal_stone", ["z"] = 17, ["param1"] = 186}, {["y"] = 23, ["x"] = 0, ["name"] = "moreblocks:coal_stone", ["z"] = 18, ["param1"] = 186}, {["y"] = 23, ["x"] = 0, ["name"] = "moreblocks:coal_stone", ["z"] = 19, ["param1"] = 186}, {["y"] = 23, ["x"] = 0, ["name"] = "moreblocks:coal_stone", ["z"] = 20, ["param1"] = 186}, {["y"] = 23, ["x"] = 0, ["name"] = "moreblocks:coal_stone", ["z"] = 21, ["param1"] = 186}, {["y"] = 23, ["x"] = 0, ["name"] = "moreblocks:coal_stone", ["z"] = 22, ["param1"] = 186}, {["y"] = 23, ["x"] = 0, ["name"] = "moreblocks:coal_stone", ["z"] = 23, ["param1"] = 186}, {["y"] = 23, ["x"] = 0, ["name"] = "moreblocks:coal_stone", ["z"] = 24, ["param1"] = 186}, {["y"] = 23, ["x"] = 0, ["name"] = "moreblocks:coal_stone", ["z"] = 25, ["param1"] = 186}, {["y"] = 23, ["x"] = 0, ["name"] = "moreblocks:coal_stone", ["z"] = 26, ["param1"] = 186}, {["y"] = 23, ["x"] = 0, ["name"] = "moreblocks:coal_stone", ["z"] = 27, ["param1"] = 186}, {["y"] = 23, ["x"] = 0, ["name"] = "moreblocks:coal_stone", ["z"] = 28, ["param1"] = 186}, {["y"] = 23, ["x"] = 0, ["name"] = "moreblocks:coal_stone", ["z"] = 29, ["param1"] = 186}, {["y"] = 23, ["x"] = 0, ["name"] = "moreblocks:coal_stone", ["z"] = 30, ["param1"] = 186}, {["y"] = 23, ["x"] = 0, ["name"] = "moreblocks:coal_stone", ["z"] = 31, ["param1"] = 186}, {["y"] = 24, ["x"] = 0, ["name"] = "moreblocks:checker_stone_tile", ["z"] = 16, ["param1"] = 46}, {["y"] = 24, ["x"] = 0, ["name"] = "moreblocks:checker_stone_tile", ["z"] = 17, ["param1"] = 46}, {["y"] = 24, ["x"] = 0, ["name"] = "moreblocks:checker_stone_tile", ["z"] = 18, ["param1"] = 46}, {["y"] = 24, ["x"] = 0, ["name"] = "moreblocks:checker_stone_tile", ["z"] = 19, ["param1"] = 46}, {["y"] = 24, ["x"] = 0, ["name"] = "moreblocks:checker_stone_tile", ["z"] = 20, ["param1"] = 46}, {["y"] = 24, ["x"] = 0, ["name"] = "moreblocks:checker_stone_tile", ["z"] = 21, ["param1"] = 46}, {["y"] = 24, ["x"] = 0, ["name"] = "moreblocks:checker_stone_tile", ["z"] = 22, ["param1"] = 46}, {["y"] = 24, ["x"] = 0, ["name"] = "moreblocks:checker_stone_tile", ["z"] = 23, ["param1"] = 46}, {["y"] = 24, ["x"] = 0, ["name"] = "moreblocks:checker_stone_tile", ["z"] = 24, ["param1"] = 46}, {["y"] = 24, ["x"] = 0, ["name"] = "moreblocks:checker_stone_tile", ["z"] = 25, ["param1"] = 46}, {["y"] = 24, ["x"] = 0, ["name"] = "moreblocks:checker_stone_tile", ["z"] = 26, ["param1"] = 46}, {["y"] = 24, ["x"] = 0, ["name"] = "moreblocks:checker_stone_tile", ["z"] = 27, ["param1"] = 46}, {["y"] = 24, ["x"] = 0, ["name"] = "moreblocks:checker_stone_tile", ["z"] = 28, ["param1"] = 46}, {["y"] = 24, ["x"] = 0, ["name"] = "moreblocks:checker_stone_tile", ["z"] = 29, ["param1"] = 46}, {["y"] = 24, ["x"] = 0, ["name"] = "moreblocks:checker_stone_tile", ["z"] = 30, ["param1"] = 46}, {["y"] = 24, ["x"] = 0, ["name"] = "moreblocks:checker_stone_tile", ["z"] = 31, ["param1"] = 46}, {["y"] = 30, ["x"] = 0, ["name"] = "moreblocks:slab_meselamp_1", ["z"] = 16, ["param2"] = 22, ["param1"] = 222}, {["y"] = 30, ["x"] = 0, ["name"] = "moreblocks:slab_meselamp_1", ["z"] = 23, ["param2"] = 23, ["param1"] = 222}, {["y"] = 30, ["x"] = 0, ["name"] = "moreblocks:slab_meselamp_1", ["z"] = 24, ["param2"] = 23, ["param1"] = 222}, {["y"] = 30, ["x"] = 0, ["name"] = "moreblocks:slab_meselamp_1", ["z"] = 31, ["param2"] = 22, ["param1"] = 222}, {["y"] = 31, ["x"] = 0, ["name"] = "moreblocks:coal_stone", ["z"] = 16, ["param1"] = 186}, {["y"] = 31, ["x"] = 0, ["name"] = "moreblocks:coal_stone", ["z"] = 17, ["param1"] = 186}, {["y"] = 31, ["x"] = 0, ["name"] = "moreblocks:coal_stone", ["z"] = 18, ["param1"] = 186}, {["y"] = 31, ["x"] = 0, ["name"] = "moreblocks:coal_stone", ["z"] = 19, ["param1"] = 186}, {["y"] = 31, ["x"] = 0, ["name"] = "moreblocks:coal_stone", ["z"] = 20, ["param1"] = 186}, {["y"] = 31, ["x"] = 0, ["name"] = "moreblocks:coal_stone", ["z"] = 21, ["param1"] = 186}, {["y"] = 31, ["x"] = 0, ["name"] = "moreblocks:coal_stone", ["z"] = 22, ["param1"] = 186}, {["y"] = 31, ["x"] = 0, ["name"] = "moreblocks:coal_stone", ["z"] = 23, ["param1"] = 186}, {["y"] = 31, ["x"] = 0, ["name"] = "moreblocks:coal_stone", ["z"] = 24, ["param1"] = 186}, {["y"] = 31, ["x"] = 0, ["name"] = "moreblocks:coal_stone", ["z"] = 25, ["param1"] = 186}, {["y"] = 31, ["x"] = 0, ["name"] = "moreblocks:coal_stone", ["z"] = 26, ["param1"] = 186}, {["y"] = 31, ["x"] = 0, ["name"] = "moreblocks:coal_stone", ["z"] = 27, ["param1"] = 186}, {["y"] = 31, ["x"] = 0, ["name"] = "moreblocks:coal_stone", ["z"] = 28, ["param1"] = 186}, {["y"] = 31, ["x"] = 0, ["name"] = "moreblocks:coal_stone", ["z"] = 29, ["param1"] = 186}, {["y"] = 31, ["x"] = 0, ["name"] = "moreblocks:coal_stone", ["z"] = 30, ["param1"] = 186}, {["y"] = 31, ["x"] = 0, ["name"] = "moreblocks:coal_stone", ["z"] = 31, ["param1"] = 186}, {["y"] = 32, ["x"] = 0, ["name"] = "moreblocks:checker_stone_tile", ["z"] = 16, ["param1"] = 46}, {["y"] = 32, ["x"] = 0, ["name"] = "moreblocks:checker_stone_tile", ["z"] = 17, ["param1"] = 46}, {["y"] = 32, ["x"] = 0, ["name"] = "moreblocks:checker_stone_tile", ["z"] = 18, ["param1"] = 46}, {["y"] = 32, ["x"] = 0, ["name"] = "moreblocks:checker_stone_tile", ["z"] = 19, ["param1"] = 46}, {["y"] = 32, ["x"] = 0, ["name"] = "moreblocks:checker_stone_tile", ["z"] = 20, ["param1"] = 46}, {["y"] = 32, ["x"] = 0, ["name"] = "moreblocks:checker_stone_tile", ["z"] = 21, ["param1"] = 46}, {["y"] = 32, ["x"] = 0, ["name"] = "moreblocks:checker_stone_tile", ["z"] = 22, ["param1"] = 46}, {["y"] = 32, ["x"] = 0, ["name"] = "moreblocks:checker_stone_tile", ["z"] = 23, ["param1"] = 46}, {["y"] = 32, ["x"] = 0, ["name"] = "moreblocks:checker_stone_tile", ["z"] = 24, ["param1"] = 46}, {["y"] = 32, ["x"] = 0, ["name"] = "moreblocks:checker_stone_tile", ["z"] = 25, ["param1"] = 46}, {["y"] = 32, ["x"] = 0, ["name"] = "moreblocks:checker_stone_tile", ["z"] = 26, ["param1"] = 46}, {["y"] = 32, ["x"] = 0, ["name"] = "moreblocks:checker_stone_tile", ["z"] = 27, ["param1"] = 46}, {["y"] = 32, ["x"] = 0, ["name"] = "moreblocks:checker_stone_tile", ["z"] = 28, ["param1"] = 46}, {["y"] = 32, ["x"] = 0, ["name"] = "moreblocks:checker_stone_tile", ["z"] = 29, ["param1"] = 46}, {["y"] = 32, ["x"] = 0, ["name"] = "moreblocks:checker_stone_tile", ["z"] = 30, ["param1"] = 46}, {["y"] = 32, ["x"] = 0, ["name"] = "moreblocks:checker_stone_tile", ["z"] = 31, ["param1"] = 46}, {["y"] = 38, ["x"] = 0, ["name"] = "moreblocks:slab_meselamp_1", ["z"] = 16, ["param2"] = 22, ["param1"] = 222}, {["y"] = 38, ["x"] = 0, ["name"] = "moreblocks:slab_meselamp_1", ["z"] = 23, ["param2"] = 23, ["param1"] = 222}, {["y"] = 38, ["x"] = 0, ["name"] = "moreblocks:slab_meselamp_1", ["z"] = 24, ["param2"] = 23, ["param1"] = 222}, {["y"] = 38, ["x"] = 0, ["name"] = "moreblocks:slab_meselamp_1", ["z"] = 31, ["param2"] = 22, ["param1"] = 222}, {["y"] = 39, ["x"] = 0, ["name"] = "moreblocks:coal_stone", ["z"] = 16, ["param1"] = 186}, {["y"] = 39, ["x"] = 0, ["name"] = "moreblocks:coal_stone", ["z"] = 17, ["param1"] = 186}, {["y"] = 39, ["x"] = 0, ["name"] = "moreblocks:coal_stone", ["z"] = 18, ["param1"] = 186}, {["y"] = 39, ["x"] = 0, ["name"] = "moreblocks:coal_stone", ["z"] = 19, ["param1"] = 186}, {["y"] = 39, ["x"] = 0, ["name"] = "moreblocks:coal_stone", ["z"] = 20, ["param1"] = 186}, {["y"] = 39, ["x"] = 0, ["name"] = "moreblocks:coal_stone", ["z"] = 21, ["param1"] = 186}, {["y"] = 39, ["x"] = 0, ["name"] = "moreblocks:coal_stone", ["z"] = 22, ["param1"] = 186}, {["y"] = 39, ["x"] = 0, ["name"] = "moreblocks:coal_stone", ["z"] = 23, ["param1"] = 186}, {["y"] = 39, ["x"] = 0, ["name"] = "moreblocks:coal_stone", ["z"] = 24, ["param1"] = 186}, {["y"] = 39, ["x"] = 0, ["name"] = "moreblocks:coal_stone", ["z"] = 25, ["param1"] = 186}, {["y"] = 39, ["x"] = 0, ["name"] = "moreblocks:coal_stone", ["z"] = 26, ["param1"] = 186}, {["y"] = 39, ["x"] = 0, ["name"] = "moreblocks:coal_stone", ["z"] = 27, ["param1"] = 186}, {["y"] = 39, ["x"] = 0, ["name"] = "moreblocks:coal_stone", ["z"] = 28, ["param1"] = 186}, {["y"] = 39, ["x"] = 0, ["name"] = "moreblocks:coal_stone", ["z"] = 29, ["param1"] = 186}, {["y"] = 39, ["x"] = 0, ["name"] = "moreblocks:coal_stone", ["z"] = 30, ["param1"] = 186}, {["y"] = 39, ["x"] = 0, ["name"] = "moreblocks:coal_stone", ["z"] = 31, ["param1"] = 186}, {["y"] = 40, ["x"] = 0, ["name"] = "moreblocks:checker_stone_tile", ["z"] = 16, ["param1"] = 46}, {["y"] = 40, ["x"] = 0, ["name"] = "moreblocks:checker_stone_tile", ["z"] = 17, ["param1"] = 46}, {["y"] = 40, ["x"] = 0, ["name"] = "moreblocks:checker_stone_tile", ["z"] = 18, ["param1"] = 46}, {["y"] = 40, ["x"] = 0, ["name"] = "moreblocks:checker_stone_tile", ["z"] = 19, ["param1"] = 46}, {["y"] = 40, ["x"] = 0, ["name"] = "moreblocks:checker_stone_tile", ["z"] = 20, ["param1"] = 46}, {["y"] = 40, ["x"] = 0, ["name"] = "moreblocks:checker_stone_tile", ["z"] = 21, ["param1"] = 46}, {["y"] = 40, ["x"] = 0, ["name"] = "moreblocks:checker_stone_tile", ["z"] = 22, ["param1"] = 46}, {["y"] = 40, ["x"] = 0, ["name"] = "moreblocks:checker_stone_tile", ["z"] = 23, ["param1"] = 46}, {["y"] = 40, ["x"] = 0, ["name"] = "moreblocks:checker_stone_tile", ["z"] = 24, ["param1"] = 46}, {["y"] = 40, ["x"] = 0, ["name"] = "moreblocks:checker_stone_tile", ["z"] = 25, ["param1"] = 46}, {["y"] = 40, ["x"] = 0, ["name"] = "moreblocks:checker_stone_tile", ["z"] = 26, ["param1"] = 46}, {["y"] = 40, ["x"] = 0, ["name"] = "moreblocks:checker_stone_tile", ["z"] = 27, ["param1"] = 46}, {["y"] = 40, ["x"] = 0, ["name"] = "moreblocks:checker_stone_tile", ["z"] = 28, ["param1"] = 46}, {["y"] = 40, ["x"] = 0, ["name"] = "moreblocks:checker_stone_tile", ["z"] = 29, ["param1"] = 46}, {["y"] = 40, ["x"] = 0, ["name"] = "moreblocks:checker_stone_tile", ["z"] = 30, ["param1"] = 46}, {["y"] = 40, ["x"] = 0, ["name"] = "moreblocks:checker_stone_tile", ["z"] = 31, ["param1"] = 46}, {["y"] = 46, ["x"] = 0, ["name"] = "moreblocks:slab_meselamp_1", ["z"] = 16, ["param2"] = 22, ["param1"] = 222}, {["y"] = 46, ["x"] = 0, ["name"] = "moreblocks:slab_meselamp_1", ["z"] = 23, ["param2"] = 23, ["param1"] = 222}, {["y"] = 46, ["x"] = 0, ["name"] = "moreblocks:slab_meselamp_1", ["z"] = 24, ["param2"] = 23, ["param1"] = 222}, {["y"] = 46, ["x"] = 0, ["name"] = "moreblocks:slab_meselamp_1", ["z"] = 31, ["param2"] = 22, ["param1"] = 222}, {["y"] = 47, ["x"] = 0, ["name"] = "moreblocks:coal_stone", ["z"] = 16, ["param1"] = 186}, {["y"] = 47, ["x"] = 0, ["name"] = "moreblocks:coal_stone", ["z"] = 17, ["param1"] = 186}, {["y"] = 47, ["x"] = 0, ["name"] = "moreblocks:coal_stone", ["z"] = 18, ["param1"] = 186}, {["y"] = 47, ["x"] = 0, ["name"] = "moreblocks:coal_stone", ["z"] = 19, ["param1"] = 186}, {["y"] = 47, ["x"] = 0, ["name"] = "moreblocks:coal_stone", ["z"] = 20, ["param1"] = 186}, {["y"] = 47, ["x"] = 0, ["name"] = "moreblocks:coal_stone", ["z"] = 21, ["param1"] = 186}, {["y"] = 47, ["x"] = 0, ["name"] = "moreblocks:coal_stone", ["z"] = 22, ["param1"] = 186}, {["y"] = 47, ["x"] = 0, ["name"] = "moreblocks:coal_stone", ["z"] = 23, ["param1"] = 186}, {["y"] = 47, ["x"] = 0, ["name"] = "moreblocks:coal_stone", ["z"] = 24, ["param1"] = 186}, {["y"] = 47, ["x"] = 0, ["name"] = "moreblocks:coal_stone", ["z"] = 25, ["param1"] = 186}, {["y"] = 47, ["x"] = 0, ["name"] = "moreblocks:coal_stone", ["z"] = 26, ["param1"] = 186}, {["y"] = 47, ["x"] = 0, ["name"] = "moreblocks:coal_stone", ["z"] = 27, ["param1"] = 186}, {["y"] = 47, ["x"] = 0, ["name"] = "moreblocks:coal_stone", ["z"] = 28, ["param1"] = 186}, {["y"] = 47, ["x"] = 0, ["name"] = "moreblocks:coal_stone", ["z"] = 29, ["param1"] = 186}, {["y"] = 47, ["x"] = 0, ["name"] = "moreblocks:coal_stone", ["z"] = 30, ["param1"] = 186}, {["y"] = 47, ["x"] = 0, ["name"] = "moreblocks:coal_stone", ["z"] = 31, ["param1"] = 186}, {["y"] = 0, ["x"] = 1, ["name"] = "default:stone", ["z"] = 16, ["param1"] = 2}, {["y"] = 0, ["x"] = 1, ["name"] = "default:stone", ["z"] = 17, ["param1"] = 2}, {["y"] = 0, ["x"] = 1, ["name"] = "default:stone", ["z"] = 18, ["param1"] = 2}, {["y"] = 0, ["x"] = 1, ["name"] = "default:stone", ["z"] = 19, ["param1"] = 2}, {["y"] = 0, ["x"] = 1, ["name"] = "default:stone", ["z"] = 20, ["param1"] = 2}, {["y"] = 0, ["x"] = 1, ["name"] = "default:stone", ["z"] = 21, ["param1"] = 2}, {["y"] = 0, ["x"] = 1, ["name"] = "default:stone", ["z"] = 22, ["param1"] = 2}, {["y"] = 0, ["x"] = 1, ["name"] = "default:stone", ["z"] = 23, ["param1"] = 2}, {["y"] = 0, ["x"] = 1, ["name"] = "default:stone", ["z"] = 24, ["param1"] = 2}, {["y"] = 0, ["x"] = 1, ["name"] = "default:stone", ["z"] = 25, ["param1"] = 2}, {["y"] = 0, ["x"] = 1, ["name"] = "default:stone", ["z"] = 26, ["param1"] = 2}, {["y"] = 0, ["x"] = 1, ["name"] = "default:stone", ["z"] = 27, ["param1"] = 2}, {["y"] = 0, ["x"] = 1, ["name"] = "default:stone", ["z"] = 28, ["param1"] = 2}, {["y"] = 0, ["x"] = 1, ["name"] = "default:stone", ["z"] = 29, ["param1"] = 2}, {["y"] = 0, ["x"] = 1, ["name"] = "default:stone", ["z"] = 30, ["param1"] = 2}, {["y"] = 0, ["x"] = 1, ["name"] = "default:stone", ["z"] = 31, ["param1"] = 2}, {["y"] = 1, ["x"] = 1, ["name"] = "default:stone", ["z"] = 16, ["param1"] = 2}, {["y"] = 1, ["x"] = 1, ["name"] = "default:stone", ["z"] = 17, ["param1"] = 2}, {["y"] = 1, ["x"] = 1, ["name"] = "default:stone", ["z"] = 18, ["param1"] = 2}, {["y"] = 1, ["x"] = 1, ["name"] = "default:stone", ["z"] = 19, ["param1"] = 2}, {["y"] = 1, ["x"] = 1, ["name"] = "default:stone", ["z"] = 20, ["param1"] = 2}, {["y"] = 1, ["x"] = 1, ["name"] = "default:stone", ["z"] = 21, ["param1"] = 2}, {["y"] = 1, ["x"] = 1, ["name"] = "default:stone", ["z"] = 22, ["param1"] = 2}, {["y"] = 1, ["x"] = 1, ["name"] = "default:stone", ["z"] = 23, ["param1"] = 2}, {["y"] = 1, ["x"] = 1, ["name"] = "default:stone", ["z"] = 24, ["param1"] = 2}, {["y"] = 1, ["x"] = 1, ["name"] = "default:stone", ["z"] = 25, ["param1"] = 2}, {["y"] = 1, ["x"] = 1, ["name"] = "default:stone", ["z"] = 26, ["param1"] = 2}, {["y"] = 1, ["x"] = 1, ["name"] = "default:stone", ["z"] = 27, ["param1"] = 2}, {["y"] = 1, ["x"] = 1, ["name"] = "default:stone", ["z"] = 28, ["param1"] = 2}, {["y"] = 1, ["x"] = 1, ["name"] = "default:stone", ["z"] = 29, ["param1"] = 2}, {["y"] = 1, ["x"] = 1, ["name"] = "default:stone", ["z"] = 30, ["param1"] = 2}, {["y"] = 1, ["x"] = 1, ["name"] = "default:stone", ["z"] = 31, ["param1"] = 2}, {["y"] = 2, ["x"] = 1, ["name"] = "default:stonebrick", ["z"] = 16, ["param2"] = 1, ["param1"] = 4}, {["y"] = 2, ["x"] = 1, ["name"] = "default:stonebrick", ["z"] = 17, ["param2"] = 1, ["param1"] = 4}, {["y"] = 2, ["x"] = 1, ["name"] = "default:stonebrick", ["z"] = 18, ["param2"] = 1, ["param1"] = 4}, {["y"] = 2, ["x"] = 1, ["name"] = "default:stonebrick", ["z"] = 19, ["param2"] = 1, ["param1"] = 4}, {["y"] = 2, ["x"] = 1, ["name"] = "default:stonebrick", ["z"] = 20, ["param2"] = 1, ["param1"] = 4}, {["y"] = 2, ["x"] = 1, ["name"] = "default:stonebrick", ["z"] = 21, ["param2"] = 1, ["param1"] = 4}, {["y"] = 2, ["x"] = 1, ["name"] = "default:stonebrick", ["z"] = 22, ["param2"] = 1, ["param1"] = 4}, {["y"] = 2, ["x"] = 1, ["name"] = "default:stonebrick", ["z"] = 23, ["param2"] = 1, ["param1"] = 4}, {["y"] = 2, ["x"] = 1, ["name"] = "default:stonebrick", ["z"] = 24, ["param2"] = 1, ["param1"] = 4}, {["y"] = 2, ["x"] = 1, ["name"] = "default:stonebrick", ["z"] = 25, ["param2"] = 1, ["param1"] = 4}, {["y"] = 2, ["x"] = 1, ["name"] = "default:stonebrick", ["z"] = 26, ["param2"] = 1, ["param1"] = 4}, {["y"] = 2, ["x"] = 1, ["name"] = "default:stonebrick", ["z"] = 27, ["param2"] = 1, ["param1"] = 4}, {["y"] = 2, ["x"] = 1, ["name"] = "default:stonebrick", ["z"] = 28, ["param2"] = 1, ["param1"] = 4}, {["y"] = 2, ["x"] = 1, ["name"] = "default:stonebrick", ["z"] = 29, ["param2"] = 1, ["param1"] = 4}, {["y"] = 2, ["x"] = 1, ["name"] = "default:stonebrick", ["z"] = 30, ["param2"] = 1, ["param1"] = 4}, {["y"] = 2, ["x"] = 1, ["name"] = "default:stonebrick", ["z"] = 31, ["param2"] = 1, ["param1"] = 4}, {["y"] = 3, ["x"] = 1, ["name"] = "moreblocks:checker_stone_tile", ["z"] = 16, ["param1"] = 46}, {["y"] = 3, ["x"] = 1, ["name"] = "moreblocks:checker_stone_tile", ["z"] = 17, ["param1"] = 46}, {["y"] = 3, ["x"] = 1, ["name"] = "moreblocks:checker_stone_tile", ["z"] = 18, ["param1"] = 46}, {["y"] = 3, ["x"] = 1, ["name"] = "moreblocks:checker_stone_tile", ["z"] = 19, ["param1"] = 46}, {["y"] = 3, ["x"] = 1, ["name"] = "moreblocks:checker_stone_tile", ["z"] = 20, ["param1"] = 46}, {["y"] = 3, ["x"] = 1, ["name"] = "moreblocks:checker_stone_tile", ["z"] = 21, ["param1"] = 46}, {["y"] = 3, ["x"] = 1, ["name"] = "moreblocks:checker_stone_tile", ["z"] = 22, ["param1"] = 46}, {["y"] = 3, ["x"] = 1, ["name"] = "moreblocks:checker_stone_tile", ["z"] = 23, ["param1"] = 46}, {["y"] = 3, ["x"] = 1, ["name"] = "moreblocks:checker_stone_tile", ["z"] = 24, ["param1"] = 46}, {["y"] = 3, ["x"] = 1, ["name"] = "moreblocks:checker_stone_tile", ["z"] = 25, ["param1"] = 46}, {["y"] = 3, ["x"] = 1, ["name"] = "moreblocks:checker_stone_tile", ["z"] = 26, ["param1"] = 46}, {["y"] = 3, ["x"] = 1, ["name"] = "moreblocks:checker_stone_tile", ["z"] = 27, ["param1"] = 46}, {["y"] = 3, ["x"] = 1, ["name"] = "moreblocks:checker_stone_tile", ["z"] = 28, ["param1"] = 46}, {["y"] = 3, ["x"] = 1, ["name"] = "moreblocks:checker_stone_tile", ["z"] = 29, ["param1"] = 46}, {["y"] = 3, ["x"] = 1, ["name"] = "moreblocks:checker_stone_tile", ["z"] = 30, ["param1"] = 46}, {["y"] = 3, ["x"] = 1, ["name"] = "moreblocks:checker_stone_tile", ["z"] = 31, ["param1"] = 46}, {["y"] = 7, ["x"] = 1, ["name"] = "moreblocks:coal_stone", ["z"] = 16, ["param1"] = 186}, {["y"] = 7, ["x"] = 1, ["name"] = "moreblocks:coal_stone", ["z"] = 17, ["param1"] = 186}, {["y"] = 7, ["x"] = 1, ["name"] = "moreblocks:coal_stone", ["z"] = 18, ["param1"] = 186}, {["y"] = 7, ["x"] = 1, ["name"] = "moreblocks:coal_stone", ["z"] = 19, ["param1"] = 186}, {["y"] = 7, ["x"] = 1, ["name"] = "moreblocks:coal_stone", ["z"] = 20, ["param1"] = 186}, {["y"] = 7, ["x"] = 1, ["name"] = "moreblocks:coal_stone", ["z"] = 21, ["param1"] = 186}, {["y"] = 7, ["x"] = 1, ["name"] = "moreblocks:coal_stone", ["z"] = 22, ["param1"] = 186}, {["y"] = 7, ["x"] = 1, ["name"] = "moreblocks:coal_stone", ["z"] = 23, ["param1"] = 186}, {["y"] = 7, ["x"] = 1, ["name"] = "moreblocks:coal_stone", ["z"] = 24, ["param1"] = 186}, {["y"] = 7, ["x"] = 1, ["name"] = "moreblocks:coal_stone", ["z"] = 25, ["param1"] = 186}, {["y"] = 7, ["x"] = 1, ["name"] = "moreblocks:coal_stone", ["z"] = 26, ["param1"] = 186}, {["y"] = 7, ["x"] = 1, ["name"] = "moreblocks:coal_stone", ["z"] = 27, ["param1"] = 186}, {["y"] = 7, ["x"] = 1, ["name"] = "moreblocks:coal_stone", ["z"] = 28, ["param1"] = 186}, {["y"] = 7, ["x"] = 1, ["name"] = "moreblocks:coal_stone", ["z"] = 29, ["param1"] = 186}, {["y"] = 7, ["x"] = 1, ["name"] = "moreblocks:coal_stone", ["z"] = 30, ["param1"] = 186}, {["y"] = 7, ["x"] = 1, ["name"] = "moreblocks:coal_stone", ["z"] = 31, ["param1"] = 186}, {["y"] = 8, ["x"] = 1, ["name"] = "moreblocks:checker_stone_tile", ["z"] = 16, ["param1"] = 46}, {["y"] = 8, ["x"] = 1, ["name"] = "moreblocks:checker_stone_tile", ["z"] = 17, ["param1"] = 46}, {["y"] = 8, ["x"] = 1, ["name"] = "moreblocks:checker_stone_tile", ["z"] = 18, ["param1"] = 46}, {["y"] = 8, ["x"] = 1, ["name"] = "moreblocks:checker_stone_tile", ["z"] = 19, ["param1"] = 46}, {["y"] = 8, ["x"] = 1, ["name"] = "moreblocks:checker_stone_tile", ["z"] = 20, ["param1"] = 46}, {["y"] = 8, ["x"] = 1, ["name"] = "moreblocks:checker_stone_tile", ["z"] = 21, ["param1"] = 46}, {["y"] = 8, ["x"] = 1, ["name"] = "moreblocks:checker_stone_tile", ["z"] = 22, ["param1"] = 46}, {["y"] = 8, ["x"] = 1, ["name"] = "moreblocks:checker_stone_tile", ["z"] = 23, ["param1"] = 46}, {["y"] = 8, ["x"] = 1, ["name"] = "moreblocks:checker_stone_tile", ["z"] = 24, ["param1"] = 46}, {["y"] = 8, ["x"] = 1, ["name"] = "moreblocks:checker_stone_tile", ["z"] = 25, ["param1"] = 46}, {["y"] = 8, ["x"] = 1, ["name"] = "moreblocks:checker_stone_tile", ["z"] = 26, ["param1"] = 46}, {["y"] = 8, ["x"] = 1, ["name"] = "moreblocks:checker_stone_tile", ["z"] = 27, ["param1"] = 46}, {["y"] = 8, ["x"] = 1, ["name"] = "moreblocks:checker_stone_tile", ["z"] = 28, ["param1"] = 46}, {["y"] = 8, ["x"] = 1, ["name"] = "moreblocks:checker_stone_tile", ["z"] = 29, ["param1"] = 46}, {["y"] = 8, ["x"] = 1, ["name"] = "moreblocks:checker_stone_tile", ["z"] = 30, ["param1"] = 46}, {["y"] = 8, ["x"] = 1, ["name"] = "moreblocks:checker_stone_tile", ["z"] = 31, ["param1"] = 46}, {["y"] = 15, ["x"] = 1, ["name"] = "moreblocks:coal_stone", ["z"] = 16, ["param1"] = 186}, {["y"] = 15, ["x"] = 1, ["name"] = "moreblocks:coal_stone", ["z"] = 17, ["param1"] = 186}, {["y"] = 15, ["x"] = 1, ["name"] = "moreblocks:coal_stone", ["z"] = 18, ["param1"] = 186}, {["y"] = 15, ["x"] = 1, ["name"] = "moreblocks:coal_stone", ["z"] = 19, ["param1"] = 186}, {["y"] = 15, ["x"] = 1, ["name"] = "moreblocks:coal_stone", ["z"] = 20, ["param1"] = 186}, {["y"] = 15, ["x"] = 1, ["name"] = "moreblocks:coal_stone", ["z"] = 21, ["param1"] = 186}, {["y"] = 15, ["x"] = 1, ["name"] = "moreblocks:coal_stone", ["z"] = 22, ["param1"] = 186}, {["y"] = 15, ["x"] = 1, ["name"] = "moreblocks:coal_stone", ["z"] = 23, ["param1"] = 186}, {["y"] = 15, ["x"] = 1, ["name"] = "moreblocks:coal_stone", ["z"] = 24, ["param1"] = 186}, {["y"] = 15, ["x"] = 1, ["name"] = "moreblocks:coal_stone", ["z"] = 25, ["param1"] = 186}, {["y"] = 15, ["x"] = 1, ["name"] = "moreblocks:coal_stone", ["z"] = 26, ["param1"] = 186}, {["y"] = 15, ["x"] = 1, ["name"] = "moreblocks:coal_stone", ["z"] = 27, ["param1"] = 186}, {["y"] = 15, ["x"] = 1, ["name"] = "moreblocks:coal_stone", ["z"] = 28, ["param1"] = 186}, {["y"] = 15, ["x"] = 1, ["name"] = "moreblocks:coal_stone", ["z"] = 29, ["param1"] = 186}, {["y"] = 15, ["x"] = 1, ["name"] = "moreblocks:coal_stone", ["z"] = 30, ["param1"] = 186}, {["y"] = 15, ["x"] = 1, ["name"] = "moreblocks:coal_stone", ["z"] = 31, ["param1"] = 186}, {["y"] = 16, ["x"] = 1, ["name"] = "moreblocks:checker_stone_tile", ["z"] = 16, ["param1"] = 46}, {["y"] = 16, ["x"] = 1, ["name"] = "moreblocks:checker_stone_tile", ["z"] = 17, ["param1"] = 46}, {["y"] = 16, ["x"] = 1, ["name"] = "moreblocks:checker_stone_tile", ["z"] = 18, ["param1"] = 46}, {["y"] = 16, ["x"] = 1, ["name"] = "moreblocks:checker_stone_tile", ["z"] = 19, ["param1"] = 46}, {["y"] = 16, ["x"] = 1, ["name"] = "moreblocks:checker_stone_tile", ["z"] = 20, ["param1"] = 46}, {["y"] = 16, ["x"] = 1, ["name"] = "moreblocks:checker_stone_tile", ["z"] = 21, ["param1"] = 46}, {["y"] = 16, ["x"] = 1, ["name"] = "moreblocks:checker_stone_tile", ["z"] = 22, ["param1"] = 46}, {["y"] = 16, ["x"] = 1, ["name"] = "moreblocks:checker_stone_tile", ["z"] = 23, ["param1"] = 46}, {["y"] = 16, ["x"] = 1, ["name"] = "moreblocks:checker_stone_tile", ["z"] = 24, ["param1"] = 46}, {["y"] = 16, ["x"] = 1, ["name"] = "moreblocks:checker_stone_tile", ["z"] = 25, ["param1"] = 46}, {["y"] = 16, ["x"] = 1, ["name"] = "moreblocks:checker_stone_tile", ["z"] = 26, ["param1"] = 46}, {["y"] = 16, ["x"] = 1, ["name"] = "moreblocks:checker_stone_tile", ["z"] = 27, ["param1"] = 46}, {["y"] = 16, ["x"] = 1, ["name"] = "moreblocks:checker_stone_tile", ["z"] = 28, ["param1"] = 46}, {["y"] = 16, ["x"] = 1, ["name"] = "moreblocks:checker_stone_tile", ["z"] = 29, ["param1"] = 46}, {["y"] = 16, ["x"] = 1, ["name"] = "moreblocks:checker_stone_tile", ["z"] = 30, ["param1"] = 46}, {["y"] = 16, ["x"] = 1, ["name"] = "moreblocks:checker_stone_tile", ["z"] = 31, ["param1"] = 46}, {["y"] = 23, ["x"] = 1, ["name"] = "moreblocks:coal_stone", ["z"] = 16, ["param1"] = 186}, {["y"] = 23, ["x"] = 1, ["name"] = "moreblocks:coal_stone", ["z"] = 17, ["param1"] = 186}, {["y"] = 23, ["x"] = 1, ["name"] = "moreblocks:coal_stone", ["z"] = 18, ["param1"] = 186}, {["y"] = 23, ["x"] = 1, ["name"] = "moreblocks:coal_stone", ["z"] = 19, ["param1"] = 186}, {["y"] = 23, ["x"] = 1, ["name"] = "moreblocks:coal_stone", ["z"] = 20, ["param1"] = 186}, {["y"] = 23, ["x"] = 1, ["name"] = "moreblocks:coal_stone", ["z"] = 21, ["param1"] = 186}, {["y"] = 23, ["x"] = 1, ["name"] = "moreblocks:coal_stone", ["z"] = 22, ["param1"] = 186}, {["y"] = 23, ["x"] = 1, ["name"] = "moreblocks:coal_stone", ["z"] = 23, ["param1"] = 186}, {["y"] = 23, ["x"] = 1, ["name"] = "moreblocks:coal_stone", ["z"] = 24, ["param1"] = 186}, {["y"] = 23, ["x"] = 1, ["name"] = "moreblocks:coal_stone", ["z"] = 25, ["param1"] = 186}, {["y"] = 23, ["x"] = 1, ["name"] = "moreblocks:coal_stone", ["z"] = 26, ["param1"] = 186}, {["y"] = 23, ["x"] = 1, ["name"] = "moreblocks:coal_stone", ["z"] = 27, ["param1"] = 186}, {["y"] = 23, ["x"] = 1, ["name"] = "moreblocks:coal_stone", ["z"] = 28, ["param1"] = 186}, {["y"] = 23, ["x"] = 1, ["name"] = "moreblocks:coal_stone", ["z"] = 29, ["param1"] = 186}, {["y"] = 23, ["x"] = 1, ["name"] = "moreblocks:coal_stone", ["z"] = 30, ["param1"] = 186}, {["y"] = 23, ["x"] = 1, ["name"] = "moreblocks:coal_stone", ["z"] = 31, ["param1"] = 186}, {["y"] = 24, ["x"] = 1, ["name"] = "moreblocks:checker_stone_tile", ["z"] = 16, ["param1"] = 46}, {["y"] = 24, ["x"] = 1, ["name"] = "moreblocks:checker_stone_tile", ["z"] = 17, ["param1"] = 46}, {["y"] = 24, ["x"] = 1, ["name"] = "moreblocks:checker_stone_tile", ["z"] = 18, ["param1"] = 46}, {["y"] = 24, ["x"] = 1, ["name"] = "moreblocks:checker_stone_tile", ["z"] = 19, ["param1"] = 46}, {["y"] = 24, ["x"] = 1, ["name"] = "moreblocks:checker_stone_tile", ["z"] = 20, ["param1"] = 46}, {["y"] = 24, ["x"] = 1, ["name"] = "moreblocks:checker_stone_tile", ["z"] = 21, ["param1"] = 46}, {["y"] = 24, ["x"] = 1, ["name"] = "moreblocks:checker_stone_tile", ["z"] = 22, ["param1"] = 46}, {["y"] = 24, ["x"] = 1, ["name"] = "moreblocks:checker_stone_tile", ["z"] = 23, ["param1"] = 46}, {["y"] = 24, ["x"] = 1, ["name"] = "moreblocks:checker_stone_tile", ["z"] = 24, ["param1"] = 46}, {["y"] = 24, ["x"] = 1, ["name"] = "moreblocks:checker_stone_tile", ["z"] = 25, ["param1"] = 46}, {["y"] = 24, ["x"] = 1, ["name"] = "moreblocks:checker_stone_tile", ["z"] = 26, ["param1"] = 46}, {["y"] = 24, ["x"] = 1, ["name"] = "moreblocks:checker_stone_tile", ["z"] = 27, ["param1"] = 46}, {["y"] = 24, ["x"] = 1, ["name"] = "moreblocks:checker_stone_tile", ["z"] = 28, ["param1"] = 46}, {["y"] = 24, ["x"] = 1, ["name"] = "moreblocks:checker_stone_tile", ["z"] = 29, ["param1"] = 46}, {["y"] = 24, ["x"] = 1, ["name"] = "moreblocks:checker_stone_tile", ["z"] = 30, ["param1"] = 46}, {["y"] = 24, ["x"] = 1, ["name"] = "moreblocks:checker_stone_tile", ["z"] = 31, ["param1"] = 46}, {["y"] = 31, ["x"] = 1, ["name"] = "moreblocks:coal_stone", ["z"] = 16, ["param1"] = 186}, {["y"] = 31, ["x"] = 1, ["name"] = "moreblocks:coal_stone", ["z"] = 17, ["param1"] = 186}, {["y"] = 31, ["x"] = 1, ["name"] = "moreblocks:coal_stone", ["z"] = 18, ["param1"] = 186}, {["y"] = 31, ["x"] = 1, ["name"] = "moreblocks:coal_stone", ["z"] = 19, ["param1"] = 186}, {["y"] = 31, ["x"] = 1, ["name"] = "moreblocks:coal_stone", ["z"] = 20, ["param1"] = 186}, {["y"] = 31, ["x"] = 1, ["name"] = "moreblocks:coal_stone", ["z"] = 21, ["param1"] = 186}, {["y"] = 31, ["x"] = 1, ["name"] = "moreblocks:coal_stone", ["z"] = 22, ["param1"] = 186}, {["y"] = 31, ["x"] = 1, ["name"] = "moreblocks:coal_stone", ["z"] = 23, ["param1"] = 186}, {["y"] = 31, ["x"] = 1, ["name"] = "moreblocks:coal_stone", ["z"] = 24, ["param1"] = 186}, {["y"] = 31, ["x"] = 1, ["name"] = "moreblocks:coal_stone", ["z"] = 25, ["param1"] = 186}, {["y"] = 31, ["x"] = 1, ["name"] = "moreblocks:coal_stone", ["z"] = 26, ["param1"] = 186}, {["y"] = 31, ["x"] = 1, ["name"] = "moreblocks:coal_stone", ["z"] = 27, ["param1"] = 186}, {["y"] = 31, ["x"] = 1, ["name"] = "moreblocks:coal_stone", ["z"] = 28, ["param1"] = 186}, {["y"] = 31, ["x"] = 1, ["name"] = "moreblocks:coal_stone", ["z"] = 29, ["param1"] = 186}, {["y"] = 31, ["x"] = 1, ["name"] = "moreblocks:coal_stone", ["z"] = 30, ["param1"] = 186}, {["y"] = 31, ["x"] = 1, ["name"] = "moreblocks:coal_stone", ["z"] = 31, ["param1"] = 186}, {["y"] = 32, ["x"] = 1, ["name"] = "moreblocks:checker_stone_tile", ["z"] = 16, ["param1"] = 46}, {["y"] = 32, ["x"] = 1, ["name"] = "moreblocks:checker_stone_tile", ["z"] = 17, ["param1"] = 46}, {["y"] = 32, ["x"] = 1, ["name"] = "moreblocks:checker_stone_tile", ["z"] = 18, ["param1"] = 46}, {["y"] = 32, ["x"] = 1, ["name"] = "moreblocks:checker_stone_tile", ["z"] = 19, ["param1"] = 46}, {["y"] = 32, ["x"] = 1, ["name"] = "moreblocks:checker_stone_tile", ["z"] = 20, ["param1"] = 46}, {["y"] = 32, ["x"] = 1, ["name"] = "moreblocks:checker_stone_tile", ["z"] = 21, ["param1"] = 46}, {["y"] = 32, ["x"] = 1, ["name"] = "moreblocks:checker_stone_tile", ["z"] = 22, ["param1"] = 46}, {["y"] = 32, ["x"] = 1, ["name"] = "moreblocks:checker_stone_tile", ["z"] = 23, ["param1"] = 46}, {["y"] = 32, ["x"] = 1, ["name"] = "moreblocks:checker_stone_tile", ["z"] = 24, ["param1"] = 46}, {["y"] = 32, ["x"] = 1, ["name"] = "moreblocks:checker_stone_tile", ["z"] = 25, ["param1"] = 46}, {["y"] = 32, ["x"] = 1, ["name"] = "moreblocks:checker_stone_tile", ["z"] = 26, ["param1"] = 46}, {["y"] = 32, ["x"] = 1, ["name"] = "moreblocks:checker_stone_tile", ["z"] = 27, ["param1"] = 46}, {["y"] = 32, ["x"] = 1, ["name"] = "moreblocks:checker_stone_tile", ["z"] = 28, ["param1"] = 46}, {["y"] = 32, ["x"] = 1, ["name"] = "moreblocks:checker_stone_tile", ["z"] = 29, ["param1"] = 46}, {["y"] = 32, ["x"] = 1, ["name"] = "moreblocks:checker_stone_tile", ["z"] = 30, ["param1"] = 46}, {["y"] = 32, ["x"] = 1, ["name"] = "moreblocks:checker_stone_tile", ["z"] = 31, ["param1"] = 46}, {["y"] = 39, ["x"] = 1, ["name"] = "moreblocks:coal_stone", ["z"] = 16, ["param1"] = 186}, {["y"] = 39, ["x"] = 1, ["name"] = "moreblocks:coal_stone", ["z"] = 17, ["param1"] = 186}, {["y"] = 39, ["x"] = 1, ["name"] = "moreblocks:coal_stone", ["z"] = 18, ["param1"] = 186}, {["y"] = 39, ["x"] = 1, ["name"] = "moreblocks:coal_stone", ["z"] = 19, ["param1"] = 186}, {["y"] = 39, ["x"] = 1, ["name"] = "moreblocks:coal_stone", ["z"] = 20, ["param1"] = 186}, {["y"] = 39, ["x"] = 1, ["name"] = "moreblocks:coal_stone", ["z"] = 21, ["param1"] = 186}, {["y"] = 39, ["x"] = 1, ["name"] = "moreblocks:coal_stone", ["z"] = 22, ["param1"] = 186}, {["y"] = 39, ["x"] = 1, ["name"] = "moreblocks:coal_stone", ["z"] = 23, ["param1"] = 186}, {["y"] = 39, ["x"] = 1, ["name"] = "moreblocks:coal_stone", ["z"] = 24, ["param1"] = 186}, {["y"] = 39, ["x"] = 1, ["name"] = "moreblocks:coal_stone", ["z"] = 25, ["param1"] = 186}, {["y"] = 39, ["x"] = 1, ["name"] = "moreblocks:coal_stone", ["z"] = 26, ["param1"] = 186}, {["y"] = 39, ["x"] = 1, ["name"] = "moreblocks:coal_stone", ["z"] = 27, ["param1"] = 186}, {["y"] = 39, ["x"] = 1, ["name"] = "moreblocks:coal_stone", ["z"] = 28, ["param1"] = 186}, {["y"] = 39, ["x"] = 1, ["name"] = "moreblocks:coal_stone", ["z"] = 29, ["param1"] = 186}, {["y"] = 39, ["x"] = 1, ["name"] = "moreblocks:coal_stone", ["z"] = 30, ["param1"] = 186}, {["y"] = 39, ["x"] = 1, ["name"] = "moreblocks:coal_stone", ["z"] = 31, ["param1"] = 186}, {["y"] = 40, ["x"] = 1, ["name"] = "moreblocks:checker_stone_tile", ["z"] = 16, ["param1"] = 46}, {["y"] = 40, ["x"] = 1, ["name"] = "moreblocks:checker_stone_tile", ["z"] = 17, ["param1"] = 46}, {["y"] = 40, ["x"] = 1, ["name"] = "moreblocks:checker_stone_tile", ["z"] = 18, ["param1"] = 46}, {["y"] = 40, ["x"] = 1, ["name"] = "moreblocks:checker_stone_tile", ["z"] = 19, ["param1"] = 46}, {["y"] = 40, ["x"] = 1, ["name"] = "moreblocks:checker_stone_tile", ["z"] = 20, ["param1"] = 46}, {["y"] = 40, ["x"] = 1, ["name"] = "moreblocks:checker_stone_tile", ["z"] = 21, ["param1"] = 46}, {["y"] = 40, ["x"] = 1, ["name"] = "moreblocks:checker_stone_tile", ["z"] = 22, ["param1"] = 46}, {["y"] = 40, ["x"] = 1, ["name"] = "moreblocks:checker_stone_tile", ["z"] = 23, ["param1"] = 46}, {["y"] = 40, ["x"] = 1, ["name"] = "moreblocks:checker_stone_tile", ["z"] = 24, ["param1"] = 46}, {["y"] = 40, ["x"] = 1, ["name"] = "moreblocks:checker_stone_tile", ["z"] = 25, ["param1"] = 46}, {["y"] = 40, ["x"] = 1, ["name"] = "moreblocks:checker_stone_tile", ["z"] = 26, ["param1"] = 46}, {["y"] = 40, ["x"] = 1, ["name"] = "moreblocks:checker_stone_tile", ["z"] = 27, ["param1"] = 46}, {["y"] = 40, ["x"] = 1, ["name"] = "moreblocks:checker_stone_tile", ["z"] = 28, ["param1"] = 46}, {["y"] = 40, ["x"] = 1, ["name"] = "moreblocks:checker_stone_tile", ["z"] = 29, ["param1"] = 46}, {["y"] = 40, ["x"] = 1, ["name"] = "moreblocks:checker_stone_tile", ["z"] = 30, ["param1"] = 46}, {["y"] = 40, ["x"] = 1, ["name"] = "moreblocks:checker_stone_tile", ["z"] = 31, ["param1"] = 46}, {["y"] = 47, ["x"] = 1, ["name"] = "moreblocks:coal_stone", ["z"] = 16, ["param1"] = 186}, {["y"] = 47, ["x"] = 1, ["name"] = "moreblocks:coal_stone", ["z"] = 17, ["param1"] = 186}, {["y"] = 47, ["x"] = 1, ["name"] = "moreblocks:coal_stone", ["z"] = 18, ["param1"] = 186}, {["y"] = 47, ["x"] = 1, ["name"] = "moreblocks:coal_stone", ["z"] = 19, ["param1"] = 186}, {["y"] = 47, ["x"] = 1, ["name"] = "moreblocks:coal_stone", ["z"] = 20, ["param1"] = 186}, {["y"] = 47, ["x"] = 1, ["name"] = "moreblocks:coal_stone", ["z"] = 21, ["param1"] = 186}, {["y"] = 47, ["x"] = 1, ["name"] = "moreblocks:coal_stone", ["z"] = 22, ["param1"] = 186}, {["y"] = 47, ["x"] = 1, ["name"] = "moreblocks:coal_stone", ["z"] = 23, ["param1"] = 186}, {["y"] = 47, ["x"] = 1, ["name"] = "moreblocks:coal_stone", ["z"] = 24, ["param1"] = 186}, {["y"] = 47, ["x"] = 1, ["name"] = "moreblocks:coal_stone", ["z"] = 25, ["param1"] = 186}, {["y"] = 47, ["x"] = 1, ["name"] = "moreblocks:coal_stone", ["z"] = 26, ["param1"] = 186}, {["y"] = 47, ["x"] = 1, ["name"] = "moreblocks:coal_stone", ["z"] = 27, ["param1"] = 186}, {["y"] = 47, ["x"] = 1, ["name"] = "moreblocks:coal_stone", ["z"] = 28, ["param1"] = 186}, {["y"] = 47, ["x"] = 1, ["name"] = "moreblocks:coal_stone", ["z"] = 29, ["param1"] = 186}, {["y"] = 47, ["x"] = 1, ["name"] = "moreblocks:coal_stone", ["z"] = 30, ["param1"] = 186}, {["y"] = 47, ["x"] = 1, ["name"] = "moreblocks:coal_stone", ["z"] = 31, ["param1"] = 186}, {["y"] = 0, ["x"] = 2, ["name"] = "default:stone", ["z"] = 16, ["param1"] = 2}, {["y"] = 0, ["x"] = 2, ["name"] = "default:stone", ["z"] = 17, ["param1"] = 2}, {["y"] = 0, ["x"] = 2, ["name"] = "default:stone", ["z"] = 18, ["param1"] = 2}, {["y"] = 0, ["x"] = 2, ["name"] = "default:stone", ["z"] = 19, ["param1"] = 2}, {["y"] = 0, ["x"] = 2, ["name"] = "default:stone", ["z"] = 20, ["param1"] = 2}, {["y"] = 0, ["x"] = 2, ["name"] = "default:stone", ["z"] = 21, ["param1"] = 2}, {["y"] = 0, ["x"] = 2, ["name"] = "default:stone", ["z"] = 22, ["param1"] = 2}, {["y"] = 0, ["x"] = 2, ["name"] = "default:stone", ["z"] = 23, ["param1"] = 2}, {["y"] = 0, ["x"] = 2, ["name"] = "default:stone", ["z"] = 24, ["param1"] = 2}, {["y"] = 0, ["x"] = 2, ["name"] = "default:stone", ["z"] = 25, ["param1"] = 2}, {["y"] = 0, ["x"] = 2, ["name"] = "default:stone", ["z"] = 26, ["param1"] = 2}, {["y"] = 0, ["x"] = 2, ["name"] = "default:stone", ["z"] = 27, ["param1"] = 2}, {["y"] = 0, ["x"] = 2, ["name"] = "default:stone", ["z"] = 28, ["param1"] = 2}, {["y"] = 0, ["x"] = 2, ["name"] = "default:stone", ["z"] = 29, ["param1"] = 2}, {["y"] = 0, ["x"] = 2, ["name"] = "default:stone", ["z"] = 30, ["param1"] = 2}, {["y"] = 0, ["x"] = 2, ["name"] = "default:stone", ["z"] = 31, ["param1"] = 2}, {["y"] = 1, ["x"] = 2, ["name"] = "default:stone", ["z"] = 16, ["param1"] = 2}, {["y"] = 1, ["x"] = 2, ["name"] = "default:stone", ["z"] = 17, ["param1"] = 2}, {["y"] = 1, ["x"] = 2, ["name"] = "default:stone", ["z"] = 18, ["param1"] = 2}, {["y"] = 1, ["x"] = 2, ["name"] = "default:stone", ["z"] = 19, ["param1"] = 2}, {["y"] = 1, ["x"] = 2, ["name"] = "default:stone", ["z"] = 20, ["param1"] = 2}, {["y"] = 1, ["x"] = 2, ["name"] = "default:stone", ["z"] = 21, ["param1"] = 2}, {["y"] = 1, ["x"] = 2, ["name"] = "default:stone", ["z"] = 22, ["param1"] = 2}, {["y"] = 1, ["x"] = 2, ["name"] = "default:stone", ["z"] = 23, ["param1"] = 2}, {["y"] = 1, ["x"] = 2, ["name"] = "default:stone", ["z"] = 24, ["param1"] = 2}, {["y"] = 1, ["x"] = 2, ["name"] = "default:stone", ["z"] = 25, ["param1"] = 2}, {["y"] = 1, ["x"] = 2, ["name"] = "default:stone", ["z"] = 26, ["param1"] = 2}, {["y"] = 1, ["x"] = 2, ["name"] = "default:stone", ["z"] = 27, ["param1"] = 2}, {["y"] = 1, ["x"] = 2, ["name"] = "default:stone", ["z"] = 28, ["param1"] = 2}, {["y"] = 1, ["x"] = 2, ["name"] = "default:stone", ["z"] = 29, ["param1"] = 2}, {["y"] = 1, ["x"] = 2, ["name"] = "default:stone", ["z"] = 30, ["param1"] = 2}, {["y"] = 1, ["x"] = 2, ["name"] = "default:stone", ["z"] = 31, ["param1"] = 2}, {["y"] = 2, ["x"] = 2, ["name"] = "default:stonebrick", ["z"] = 16, ["param2"] = 1, ["param1"] = 4}, {["y"] = 2, ["x"] = 2, ["name"] = "default:stonebrick", ["z"] = 17, ["param2"] = 1, ["param1"] = 4}, {["y"] = 2, ["x"] = 2, ["name"] = "default:stonebrick", ["z"] = 18, ["param2"] = 1, ["param1"] = 4}, {["y"] = 2, ["x"] = 2, ["name"] = "default:stonebrick", ["z"] = 19, ["param2"] = 1, ["param1"] = 4}, {["y"] = 2, ["x"] = 2, ["name"] = "default:stonebrick", ["z"] = 20, ["param2"] = 1, ["param1"] = 4}, {["y"] = 2, ["x"] = 2, ["name"] = "default:stonebrick", ["z"] = 21, ["param2"] = 1, ["param1"] = 4}, {["y"] = 2, ["x"] = 2, ["name"] = "default:stonebrick", ["z"] = 22, ["param2"] = 1, ["param1"] = 4}, {["y"] = 2, ["x"] = 2, ["name"] = "default:stonebrick", ["z"] = 23, ["param2"] = 1, ["param1"] = 4}, {["y"] = 2, ["x"] = 2, ["name"] = "default:stonebrick", ["z"] = 24, ["param2"] = 1, ["param1"] = 4}, {["y"] = 2, ["x"] = 2, ["name"] = "default:stonebrick", ["z"] = 25, ["param2"] = 1, ["param1"] = 4}, {["y"] = 2, ["x"] = 2, ["name"] = "default:stonebrick", ["z"] = 26, ["param2"] = 1, ["param1"] = 4}, {["y"] = 2, ["x"] = 2, ["name"] = "default:stonebrick", ["z"] = 27, ["param2"] = 1, ["param1"] = 4}, {["y"] = 2, ["x"] = 2, ["name"] = "default:stonebrick", ["z"] = 28, ["param2"] = 1, ["param1"] = 4}, {["y"] = 2, ["x"] = 2, ["name"] = "default:stonebrick", ["z"] = 29, ["param2"] = 1, ["param1"] = 4}, {["y"] = 2, ["x"] = 2, ["name"] = "default:stonebrick", ["z"] = 30, ["param2"] = 1, ["param1"] = 4}, {["y"] = 2, ["x"] = 2, ["name"] = "default:stonebrick", ["z"] = 31, ["param2"] = 1, ["param1"] = 4}, {["y"] = 3, ["x"] = 2, ["name"] = "moreblocks:checker_stone_tile", ["z"] = 16, ["param1"] = 46}, {["y"] = 3, ["x"] = 2, ["name"] = "moreblocks:checker_stone_tile", ["z"] = 17, ["param1"] = 46}, {["y"] = 3, ["x"] = 2, ["name"] = "moreblocks:checker_stone_tile", ["z"] = 18, ["param1"] = 46}, {["y"] = 3, ["x"] = 2, ["name"] = "moreblocks:checker_stone_tile", ["z"] = 19, ["param1"] = 46}, {["y"] = 3, ["x"] = 2, ["name"] = "moreblocks:checker_stone_tile", ["z"] = 20, ["param1"] = 46}, {["y"] = 3, ["x"] = 2, ["name"] = "moreblocks:checker_stone_tile", ["z"] = 21, ["param1"] = 46}, {["y"] = 3, ["x"] = 2, ["name"] = "moreblocks:checker_stone_tile", ["z"] = 22, ["param1"] = 46}, {["y"] = 3, ["x"] = 2, ["name"] = "moreblocks:checker_stone_tile", ["z"] = 23, ["param1"] = 46}, {["y"] = 3, ["x"] = 2, ["name"] = "moreblocks:checker_stone_tile", ["z"] = 24, ["param1"] = 46}, {["y"] = 3, ["x"] = 2, ["name"] = "moreblocks:checker_stone_tile", ["z"] = 25, ["param1"] = 46}, {["y"] = 3, ["x"] = 2, ["name"] = "moreblocks:checker_stone_tile", ["z"] = 26, ["param1"] = 46}, {["y"] = 3, ["x"] = 2, ["name"] = "moreblocks:checker_stone_tile", ["z"] = 27, ["param1"] = 46}, {["y"] = 3, ["x"] = 2, ["name"] = "moreblocks:checker_stone_tile", ["z"] = 28, ["param1"] = 46}, {["y"] = 3, ["x"] = 2, ["name"] = "moreblocks:checker_stone_tile", ["z"] = 29, ["param1"] = 46}, {["y"] = 3, ["x"] = 2, ["name"] = "moreblocks:checker_stone_tile", ["z"] = 30, ["param1"] = 46}, {["y"] = 3, ["x"] = 2, ["name"] = "moreblocks:checker_stone_tile", ["z"] = 31, ["param1"] = 46}, {["y"] = 7, ["x"] = 2, ["name"] = "moreblocks:coal_stone", ["z"] = 16, ["param1"] = 186}, {["y"] = 7, ["x"] = 2, ["name"] = "moreblocks:coal_stone", ["z"] = 17, ["param1"] = 186}, {["y"] = 7, ["x"] = 2, ["name"] = "moreblocks:coal_stone", ["z"] = 18, ["param1"] = 186}, {["y"] = 7, ["x"] = 2, ["name"] = "moreblocks:coal_stone", ["z"] = 19, ["param1"] = 186}, {["y"] = 7, ["x"] = 2, ["name"] = "moreblocks:coal_stone", ["z"] = 20, ["param1"] = 186}, {["y"] = 7, ["x"] = 2, ["name"] = "moreblocks:coal_stone", ["z"] = 21, ["param1"] = 186}, {["y"] = 7, ["x"] = 2, ["name"] = "moreblocks:coal_stone", ["z"] = 22, ["param1"] = 186}, {["y"] = 7, ["x"] = 2, ["name"] = "moreblocks:coal_stone", ["z"] = 23, ["param1"] = 186}, {["y"] = 7, ["x"] = 2, ["name"] = "moreblocks:coal_stone", ["z"] = 24, ["param1"] = 186}, {["y"] = 7, ["x"] = 2, ["name"] = "moreblocks:coal_stone", ["z"] = 25, ["param1"] = 186}, {["y"] = 7, ["x"] = 2, ["name"] = "moreblocks:coal_stone", ["z"] = 26, ["param1"] = 186}, {["y"] = 7, ["x"] = 2, ["name"] = "moreblocks:coal_stone", ["z"] = 27, ["param1"] = 186}, {["y"] = 7, ["x"] = 2, ["name"] = "moreblocks:coal_stone", ["z"] = 28, ["param1"] = 186}, {["y"] = 7, ["x"] = 2, ["name"] = "moreblocks:coal_stone", ["z"] = 29, ["param1"] = 186}, {["y"] = 7, ["x"] = 2, ["name"] = "moreblocks:coal_stone", ["z"] = 30, ["param1"] = 186}, {["y"] = 7, ["x"] = 2, ["name"] = "moreblocks:coal_stone", ["z"] = 31, ["param1"] = 186}, {["y"] = 8, ["x"] = 2, ["name"] = "moreblocks:checker_stone_tile", ["z"] = 16, ["param1"] = 46}, {["y"] = 8, ["x"] = 2, ["name"] = "moreblocks:checker_stone_tile", ["z"] = 17, ["param1"] = 46}, {["y"] = 8, ["x"] = 2, ["name"] = "moreblocks:checker_stone_tile", ["z"] = 18, ["param1"] = 46}, {["y"] = 8, ["x"] = 2, ["name"] = "moreblocks:checker_stone_tile", ["z"] = 19, ["param1"] = 46}, {["y"] = 8, ["x"] = 2, ["name"] = "moreblocks:checker_stone_tile", ["z"] = 20, ["param1"] = 46}, {["y"] = 8, ["x"] = 2, ["name"] = "moreblocks:checker_stone_tile", ["z"] = 21, ["param1"] = 46}, {["y"] = 8, ["x"] = 2, ["name"] = "moreblocks:checker_stone_tile", ["z"] = 22, ["param1"] = 46}, {["y"] = 8, ["x"] = 2, ["name"] = "moreblocks:checker_stone_tile", ["z"] = 23, ["param1"] = 46}, {["y"] = 8, ["x"] = 2, ["name"] = "moreblocks:checker_stone_tile", ["z"] = 24, ["param1"] = 46}, {["y"] = 8, ["x"] = 2, ["name"] = "moreblocks:checker_stone_tile", ["z"] = 25, ["param1"] = 46}, {["y"] = 8, ["x"] = 2, ["name"] = "moreblocks:checker_stone_tile", ["z"] = 26, ["param1"] = 46}, {["y"] = 8, ["x"] = 2, ["name"] = "moreblocks:checker_stone_tile", ["z"] = 27, ["param1"] = 46}, {["y"] = 8, ["x"] = 2, ["name"] = "moreblocks:checker_stone_tile", ["z"] = 28, ["param1"] = 46}, {["y"] = 8, ["x"] = 2, ["name"] = "moreblocks:checker_stone_tile", ["z"] = 29, ["param1"] = 46}, {["y"] = 8, ["x"] = 2, ["name"] = "moreblocks:checker_stone_tile", ["z"] = 30, ["param1"] = 46}, {["y"] = 8, ["x"] = 2, ["name"] = "moreblocks:checker_stone_tile", ["z"] = 31, ["param1"] = 46}, {["y"] = 15, ["x"] = 2, ["name"] = "moreblocks:coal_stone", ["z"] = 16, ["param1"] = 186}, {["y"] = 15, ["x"] = 2, ["name"] = "moreblocks:coal_stone", ["z"] = 17, ["param1"] = 186}, {["y"] = 15, ["x"] = 2, ["name"] = "moreblocks:coal_stone", ["z"] = 18, ["param1"] = 186}, {["y"] = 15, ["x"] = 2, ["name"] = "moreblocks:coal_stone", ["z"] = 19, ["param1"] = 186}, {["y"] = 15, ["x"] = 2, ["name"] = "moreblocks:coal_stone", ["z"] = 20, ["param1"] = 186}, {["y"] = 15, ["x"] = 2, ["name"] = "moreblocks:coal_stone", ["z"] = 21, ["param1"] = 186}, {["y"] = 15, ["x"] = 2, ["name"] = "moreblocks:coal_stone", ["z"] = 22, ["param1"] = 186}, {["y"] = 15, ["x"] = 2, ["name"] = "moreblocks:coal_stone", ["z"] = 23, ["param1"] = 186}, {["y"] = 15, ["x"] = 2, ["name"] = "moreblocks:coal_stone", ["z"] = 24, ["param1"] = 186}, {["y"] = 15, ["x"] = 2, ["name"] = "moreblocks:coal_stone", ["z"] = 25, ["param1"] = 186}, {["y"] = 15, ["x"] = 2, ["name"] = "moreblocks:coal_stone", ["z"] = 26, ["param1"] = 186}, {["y"] = 15, ["x"] = 2, ["name"] = "moreblocks:coal_stone", ["z"] = 27, ["param1"] = 186}, {["y"] = 15, ["x"] = 2, ["name"] = "moreblocks:coal_stone", ["z"] = 28, ["param1"] = 186}, {["y"] = 15, ["x"] = 2, ["name"] = "moreblocks:coal_stone", ["z"] = 29, ["param1"] = 186}, {["y"] = 15, ["x"] = 2, ["name"] = "moreblocks:coal_stone", ["z"] = 30, ["param1"] = 186}, {["y"] = 15, ["x"] = 2, ["name"] = "moreblocks:coal_stone", ["z"] = 31, ["param1"] = 186}, {["y"] = 16, ["x"] = 2, ["name"] = "moreblocks:checker_stone_tile", ["z"] = 16, ["param1"] = 46}, {["y"] = 16, ["x"] = 2, ["name"] = "moreblocks:checker_stone_tile", ["z"] = 17, ["param1"] = 46}, {["y"] = 16, ["x"] = 2, ["name"] = "moreblocks:checker_stone_tile", ["z"] = 18, ["param1"] = 46}, {["y"] = 16, ["x"] = 2, ["name"] = "moreblocks:checker_stone_tile", ["z"] = 19, ["param1"] = 46}, {["y"] = 16, ["x"] = 2, ["name"] = "moreblocks:checker_stone_tile", ["z"] = 20, ["param1"] = 46}, {["y"] = 16, ["x"] = 2, ["name"] = "moreblocks:checker_stone_tile", ["z"] = 21, ["param1"] = 46}, {["y"] = 16, ["x"] = 2, ["name"] = "moreblocks:checker_stone_tile", ["z"] = 22, ["param1"] = 46}, {["y"] = 16, ["x"] = 2, ["name"] = "moreblocks:checker_stone_tile", ["z"] = 23, ["param1"] = 46}, {["y"] = 16, ["x"] = 2, ["name"] = "moreblocks:checker_stone_tile", ["z"] = 24, ["param1"] = 46}, {["y"] = 16, ["x"] = 2, ["name"] = "moreblocks:checker_stone_tile", ["z"] = 25, ["param1"] = 46}, {["y"] = 16, ["x"] = 2, ["name"] = "moreblocks:checker_stone_tile", ["z"] = 26, ["param1"] = 46}, {["y"] = 16, ["x"] = 2, ["name"] = "moreblocks:checker_stone_tile", ["z"] = 27, ["param1"] = 46}, {["y"] = 16, ["x"] = 2, ["name"] = "moreblocks:checker_stone_tile", ["z"] = 28, ["param1"] = 46}, {["y"] = 16, ["x"] = 2, ["name"] = "moreblocks:checker_stone_tile", ["z"] = 29, ["param1"] = 46}, {["y"] = 16, ["x"] = 2, ["name"] = "moreblocks:checker_stone_tile", ["z"] = 30, ["param1"] = 46}, {["y"] = 16, ["x"] = 2, ["name"] = "moreblocks:checker_stone_tile", ["z"] = 31, ["param1"] = 46}, {["y"] = 23, ["x"] = 2, ["name"] = "moreblocks:coal_stone", ["z"] = 16, ["param1"] = 186}, {["y"] = 23, ["x"] = 2, ["name"] = "moreblocks:coal_stone", ["z"] = 17, ["param1"] = 186}, {["y"] = 23, ["x"] = 2, ["name"] = "moreblocks:coal_stone", ["z"] = 18, ["param1"] = 186}, {["y"] = 23, ["x"] = 2, ["name"] = "moreblocks:coal_stone", ["z"] = 19, ["param1"] = 186}, {["y"] = 23, ["x"] = 2, ["name"] = "moreblocks:coal_stone", ["z"] = 20, ["param1"] = 186}, {["y"] = 23, ["x"] = 2, ["name"] = "moreblocks:coal_stone", ["z"] = 21, ["param1"] = 186}, {["y"] = 23, ["x"] = 2, ["name"] = "moreblocks:coal_stone", ["z"] = 22, ["param1"] = 186}, {["y"] = 23, ["x"] = 2, ["name"] = "moreblocks:coal_stone", ["z"] = 23, ["param1"] = 186}, {["y"] = 23, ["x"] = 2, ["name"] = "moreblocks:coal_stone", ["z"] = 24, ["param1"] = 186}, {["y"] = 23, ["x"] = 2, ["name"] = "moreblocks:coal_stone", ["z"] = 25, ["param1"] = 186}, {["y"] = 23, ["x"] = 2, ["name"] = "moreblocks:coal_stone", ["z"] = 26, ["param1"] = 186}, {["y"] = 23, ["x"] = 2, ["name"] = "moreblocks:coal_stone", ["z"] = 27, ["param1"] = 186}, {["y"] = 23, ["x"] = 2, ["name"] = "moreblocks:coal_stone", ["z"] = 28, ["param1"] = 186}, {["y"] = 23, ["x"] = 2, ["name"] = "moreblocks:coal_stone", ["z"] = 29, ["param1"] = 186}, {["y"] = 23, ["x"] = 2, ["name"] = "moreblocks:coal_stone", ["z"] = 30, ["param1"] = 186}, {["y"] = 23, ["x"] = 2, ["name"] = "moreblocks:coal_stone", ["z"] = 31, ["param1"] = 186}, {["y"] = 24, ["x"] = 2, ["name"] = "moreblocks:checker_stone_tile", ["z"] = 16, ["param1"] = 46}, {["y"] = 24, ["x"] = 2, ["name"] = "moreblocks:checker_stone_tile", ["z"] = 17, ["param1"] = 46}, {["y"] = 24, ["x"] = 2, ["name"] = "moreblocks:checker_stone_tile", ["z"] = 18, ["param1"] = 46}, {["y"] = 24, ["x"] = 2, ["name"] = "moreblocks:checker_stone_tile", ["z"] = 19, ["param1"] = 46}, {["y"] = 24, ["x"] = 2, ["name"] = "moreblocks:checker_stone_tile", ["z"] = 20, ["param1"] = 46}, {["y"] = 24, ["x"] = 2, ["name"] = "moreblocks:checker_stone_tile", ["z"] = 21, ["param1"] = 46}, {["y"] = 24, ["x"] = 2, ["name"] = "moreblocks:checker_stone_tile", ["z"] = 22, ["param1"] = 46}, {["y"] = 24, ["x"] = 2, ["name"] = "moreblocks:checker_stone_tile", ["z"] = 23, ["param1"] = 46}, {["y"] = 24, ["x"] = 2, ["name"] = "moreblocks:checker_stone_tile", ["z"] = 24, ["param1"] = 46}, {["y"] = 24, ["x"] = 2, ["name"] = "moreblocks:checker_stone_tile", ["z"] = 25, ["param1"] = 46}, {["y"] = 24, ["x"] = 2, ["name"] = "moreblocks:checker_stone_tile", ["z"] = 26, ["param1"] = 46}, {["y"] = 24, ["x"] = 2, ["name"] = "moreblocks:checker_stone_tile", ["z"] = 27, ["param1"] = 46}, {["y"] = 24, ["x"] = 2, ["name"] = "moreblocks:checker_stone_tile", ["z"] = 28, ["param1"] = 46}, {["y"] = 24, ["x"] = 2, ["name"] = "moreblocks:checker_stone_tile", ["z"] = 29, ["param1"] = 46}, {["y"] = 24, ["x"] = 2, ["name"] = "moreblocks:checker_stone_tile", ["z"] = 30, ["param1"] = 46}, {["y"] = 24, ["x"] = 2, ["name"] = "moreblocks:checker_stone_tile", ["z"] = 31, ["param1"] = 46}, {["y"] = 31, ["x"] = 2, ["name"] = "moreblocks:coal_stone", ["z"] = 16, ["param1"] = 186}, {["y"] = 31, ["x"] = 2, ["name"] = "moreblocks:coal_stone", ["z"] = 17, ["param1"] = 186}, {["y"] = 31, ["x"] = 2, ["name"] = "moreblocks:coal_stone", ["z"] = 18, ["param1"] = 186}, {["y"] = 31, ["x"] = 2, ["name"] = "moreblocks:coal_stone", ["z"] = 19, ["param1"] = 186}, {["y"] = 31, ["x"] = 2, ["name"] = "moreblocks:coal_stone", ["z"] = 20, ["param1"] = 186}, {["y"] = 31, ["x"] = 2, ["name"] = "moreblocks:coal_stone", ["z"] = 21, ["param1"] = 186}, {["y"] = 31, ["x"] = 2, ["name"] = "moreblocks:coal_stone", ["z"] = 22, ["param1"] = 186}, {["y"] = 31, ["x"] = 2, ["name"] = "moreblocks:coal_stone", ["z"] = 23, ["param1"] = 186}, {["y"] = 31, ["x"] = 2, ["name"] = "moreblocks:coal_stone", ["z"] = 24, ["param1"] = 186}, {["y"] = 31, ["x"] = 2, ["name"] = "moreblocks:coal_stone", ["z"] = 25, ["param1"] = 186}, {["y"] = 31, ["x"] = 2, ["name"] = "moreblocks:coal_stone", ["z"] = 26, ["param1"] = 186}, {["y"] = 31, ["x"] = 2, ["name"] = "moreblocks:coal_stone", ["z"] = 27, ["param1"] = 186}, {["y"] = 31, ["x"] = 2, ["name"] = "moreblocks:coal_stone", ["z"] = 28, ["param1"] = 186}, {["y"] = 31, ["x"] = 2, ["name"] = "moreblocks:coal_stone", ["z"] = 29, ["param1"] = 186}, {["y"] = 31, ["x"] = 2, ["name"] = "moreblocks:coal_stone", ["z"] = 30, ["param1"] = 186}, {["y"] = 31, ["x"] = 2, ["name"] = "moreblocks:coal_stone", ["z"] = 31, ["param1"] = 186}, {["y"] = 32, ["x"] = 2, ["name"] = "moreblocks:checker_stone_tile", ["z"] = 16, ["param1"] = 46}, {["y"] = 32, ["x"] = 2, ["name"] = "moreblocks:checker_stone_tile", ["z"] = 17, ["param1"] = 46}, {["y"] = 32, ["x"] = 2, ["name"] = "moreblocks:checker_stone_tile", ["z"] = 18, ["param1"] = 46}, {["y"] = 32, ["x"] = 2, ["name"] = "moreblocks:checker_stone_tile", ["z"] = 19, ["param1"] = 46}, {["y"] = 32, ["x"] = 2, ["name"] = "moreblocks:checker_stone_tile", ["z"] = 20, ["param1"] = 46}, {["y"] = 32, ["x"] = 2, ["name"] = "moreblocks:checker_stone_tile", ["z"] = 21, ["param1"] = 46}, {["y"] = 32, ["x"] = 2, ["name"] = "moreblocks:checker_stone_tile", ["z"] = 22, ["param1"] = 46}, {["y"] = 32, ["x"] = 2, ["name"] = "moreblocks:checker_stone_tile", ["z"] = 23, ["param1"] = 46}, {["y"] = 32, ["x"] = 2, ["name"] = "moreblocks:checker_stone_tile", ["z"] = 24, ["param1"] = 46}, {["y"] = 32, ["x"] = 2, ["name"] = "moreblocks:checker_stone_tile", ["z"] = 25, ["param1"] = 46}, {["y"] = 32, ["x"] = 2, ["name"] = "moreblocks:checker_stone_tile", ["z"] = 26, ["param1"] = 46}, {["y"] = 32, ["x"] = 2, ["name"] = "moreblocks:checker_stone_tile", ["z"] = 27, ["param1"] = 46}, {["y"] = 32, ["x"] = 2, ["name"] = "moreblocks:checker_stone_tile", ["z"] = 28, ["param1"] = 46}, {["y"] = 32, ["x"] = 2, ["name"] = "moreblocks:checker_stone_tile", ["z"] = 29, ["param1"] = 46}, {["y"] = 32, ["x"] = 2, ["name"] = "moreblocks:checker_stone_tile", ["z"] = 30, ["param1"] = 46}, {["y"] = 32, ["x"] = 2, ["name"] = "moreblocks:checker_stone_tile", ["z"] = 31, ["param1"] = 46}, {["y"] = 39, ["x"] = 2, ["name"] = "moreblocks:coal_stone", ["z"] = 16, ["param1"] = 186}, {["y"] = 39, ["x"] = 2, ["name"] = "moreblocks:coal_stone", ["z"] = 17, ["param1"] = 186}, {["y"] = 39, ["x"] = 2, ["name"] = "moreblocks:coal_stone", ["z"] = 18, ["param1"] = 186}, {["y"] = 39, ["x"] = 2, ["name"] = "moreblocks:coal_stone", ["z"] = 19, ["param1"] = 186}, {["y"] = 39, ["x"] = 2, ["name"] = "moreblocks:coal_stone", ["z"] = 20, ["param1"] = 186}, {["y"] = 39, ["x"] = 2, ["name"] = "moreblocks:coal_stone", ["z"] = 21, ["param1"] = 186}, {["y"] = 39, ["x"] = 2, ["name"] = "moreblocks:coal_stone", ["z"] = 22, ["param1"] = 186}, {["y"] = 39, ["x"] = 2, ["name"] = "moreblocks:coal_stone", ["z"] = 23, ["param1"] = 186}, {["y"] = 39, ["x"] = 2, ["name"] = "moreblocks:coal_stone", ["z"] = 24, ["param1"] = 186}, {["y"] = 39, ["x"] = 2, ["name"] = "moreblocks:coal_stone", ["z"] = 25, ["param1"] = 186}, {["y"] = 39, ["x"] = 2, ["name"] = "moreblocks:coal_stone", ["z"] = 26, ["param1"] = 186}, {["y"] = 39, ["x"] = 2, ["name"] = "moreblocks:coal_stone", ["z"] = 27, ["param1"] = 186}, {["y"] = 39, ["x"] = 2, ["name"] = "moreblocks:coal_stone", ["z"] = 28, ["param1"] = 186}, {["y"] = 39, ["x"] = 2, ["name"] = "moreblocks:coal_stone", ["z"] = 29, ["param1"] = 186}, {["y"] = 39, ["x"] = 2, ["name"] = "moreblocks:coal_stone", ["z"] = 30, ["param1"] = 186}, {["y"] = 39, ["x"] = 2, ["name"] = "moreblocks:coal_stone", ["z"] = 31, ["param1"] = 186}, {["y"] = 40, ["x"] = 2, ["name"] = "moreblocks:checker_stone_tile", ["z"] = 16, ["param1"] = 46}, {["y"] = 40, ["x"] = 2, ["name"] = "moreblocks:checker_stone_tile", ["z"] = 17, ["param1"] = 46}, {["y"] = 40, ["x"] = 2, ["name"] = "moreblocks:checker_stone_tile", ["z"] = 18, ["param1"] = 46}, {["y"] = 40, ["x"] = 2, ["name"] = "moreblocks:checker_stone_tile", ["z"] = 19, ["param1"] = 46}, {["y"] = 40, ["x"] = 2, ["name"] = "moreblocks:checker_stone_tile", ["z"] = 20, ["param1"] = 46}, {["y"] = 40, ["x"] = 2, ["name"] = "moreblocks:checker_stone_tile", ["z"] = 21, ["param1"] = 46}, {["y"] = 40, ["x"] = 2, ["name"] = "moreblocks:checker_stone_tile", ["z"] = 22, ["param1"] = 46}, {["y"] = 40, ["x"] = 2, ["name"] = "moreblocks:checker_stone_tile", ["z"] = 23, ["param1"] = 46}, {["y"] = 40, ["x"] = 2, ["name"] = "moreblocks:checker_stone_tile", ["z"] = 24, ["param1"] = 46}, {["y"] = 40, ["x"] = 2, ["name"] = "moreblocks:checker_stone_tile", ["z"] = 25, ["param1"] = 46}, {["y"] = 40, ["x"] = 2, ["name"] = "moreblocks:checker_stone_tile", ["z"] = 26, ["param1"] = 46}, {["y"] = 40, ["x"] = 2, ["name"] = "moreblocks:checker_stone_tile", ["z"] = 27, ["param1"] = 46}, {["y"] = 40, ["x"] = 2, ["name"] = "moreblocks:checker_stone_tile", ["z"] = 28, ["param1"] = 46}, {["y"] = 40, ["x"] = 2, ["name"] = "moreblocks:checker_stone_tile", ["z"] = 29, ["param1"] = 46}, {["y"] = 40, ["x"] = 2, ["name"] = "moreblocks:checker_stone_tile", ["z"] = 30, ["param1"] = 46}, {["y"] = 40, ["x"] = 2, ["name"] = "moreblocks:checker_stone_tile", ["z"] = 31, ["param1"] = 46}, {["y"] = 47, ["x"] = 2, ["name"] = "moreblocks:coal_stone", ["z"] = 16, ["param1"] = 186}, {["y"] = 47, ["x"] = 2, ["name"] = "moreblocks:coal_stone", ["z"] = 17, ["param1"] = 186}, {["y"] = 47, ["x"] = 2, ["name"] = "moreblocks:coal_stone", ["z"] = 18, ["param1"] = 186}, {["y"] = 47, ["x"] = 2, ["name"] = "moreblocks:coal_stone", ["z"] = 19, ["param1"] = 186}, {["y"] = 47, ["x"] = 2, ["name"] = "moreblocks:coal_stone", ["z"] = 20, ["param1"] = 186}, {["y"] = 47, ["x"] = 2, ["name"] = "moreblocks:coal_stone", ["z"] = 21, ["param1"] = 186}, {["y"] = 47, ["x"] = 2, ["name"] = "moreblocks:coal_stone", ["z"] = 22, ["param1"] = 186}, {["y"] = 47, ["x"] = 2, ["name"] = "moreblocks:coal_stone", ["z"] = 23, ["param1"] = 186}, {["y"] = 47, ["x"] = 2, ["name"] = "moreblocks:coal_stone", ["z"] = 24, ["param1"] = 186}, {["y"] = 47, ["x"] = 2, ["name"] = "moreblocks:coal_stone", ["z"] = 25, ["param1"] = 186}, {["y"] = 47, ["x"] = 2, ["name"] = "moreblocks:coal_stone", ["z"] = 26, ["param1"] = 186}, {["y"] = 47, ["x"] = 2, ["name"] = "moreblocks:coal_stone", ["z"] = 27, ["param1"] = 186}, {["y"] = 47, ["x"] = 2, ["name"] = "moreblocks:coal_stone", ["z"] = 28, ["param1"] = 186}, {["y"] = 47, ["x"] = 2, ["name"] = "moreblocks:coal_stone", ["z"] = 29, ["param1"] = 186}, {["y"] = 47, ["x"] = 2, ["name"] = "moreblocks:coal_stone", ["z"] = 30, ["param1"] = 186}, {["y"] = 47, ["x"] = 2, ["name"] = "moreblocks:coal_stone", ["z"] = 31, ["param1"] = 186}, {["y"] = 0, ["x"] = 3, ["name"] = "default:stone", ["z"] = 16, ["param1"] = 2}, {["y"] = 0, ["x"] = 3, ["name"] = "default:stone", ["z"] = 17, ["param1"] = 2}, {["y"] = 0, ["x"] = 3, ["name"] = "default:stone", ["z"] = 18, ["param1"] = 2}, {["y"] = 0, ["x"] = 3, ["name"] = "default:stone", ["z"] = 19, ["param1"] = 2}, {["y"] = 0, ["x"] = 3, ["name"] = "default:stone", ["z"] = 20, ["param1"] = 2}, {["y"] = 0, ["x"] = 3, ["name"] = "default:stone", ["z"] = 21, ["param1"] = 2}, {["y"] = 0, ["x"] = 3, ["name"] = "default:stone", ["z"] = 22, ["param1"] = 2}, {["y"] = 0, ["x"] = 3, ["name"] = "default:stone", ["z"] = 23, ["param1"] = 2}, {["y"] = 0, ["x"] = 3, ["name"] = "default:stone", ["z"] = 24, ["param1"] = 2}, {["y"] = 0, ["x"] = 3, ["name"] = "default:stone", ["z"] = 25, ["param1"] = 2}, {["y"] = 0, ["x"] = 3, ["name"] = "default:stone", ["z"] = 26, ["param1"] = 2}, {["y"] = 0, ["x"] = 3, ["name"] = "default:stone", ["z"] = 27, ["param1"] = 2}, {["y"] = 0, ["x"] = 3, ["name"] = "default:stone", ["z"] = 28, ["param1"] = 2}, {["y"] = 0, ["x"] = 3, ["name"] = "default:stone", ["z"] = 29, ["param1"] = 2}, {["y"] = 0, ["x"] = 3, ["name"] = "default:stone", ["z"] = 30, ["param1"] = 2}, {["y"] = 0, ["x"] = 3, ["name"] = "default:stone", ["z"] = 31, ["param1"] = 2}, {["y"] = 1, ["x"] = 3, ["name"] = "default:stone", ["z"] = 16, ["param1"] = 2}, {["y"] = 1, ["x"] = 3, ["name"] = "default:stone", ["z"] = 17, ["param1"] = 2}, {["y"] = 1, ["x"] = 3, ["name"] = "default:stone", ["z"] = 18, ["param1"] = 2}, {["y"] = 1, ["x"] = 3, ["name"] = "default:stone", ["z"] = 19, ["param1"] = 2}, {["y"] = 1, ["x"] = 3, ["name"] = "default:stone", ["z"] = 20, ["param1"] = 2}, {["y"] = 1, ["x"] = 3, ["name"] = "default:stone", ["z"] = 21, ["param1"] = 2}, {["y"] = 1, ["x"] = 3, ["name"] = "default:stone", ["z"] = 22, ["param1"] = 2}, {["y"] = 1, ["x"] = 3, ["name"] = "default:stone", ["z"] = 23, ["param1"] = 2}, {["y"] = 1, ["x"] = 3, ["name"] = "default:stone", ["z"] = 24, ["param1"] = 2}, {["y"] = 1, ["x"] = 3, ["name"] = "default:stone", ["z"] = 25, ["param1"] = 2}, {["y"] = 1, ["x"] = 3, ["name"] = "default:stone", ["z"] = 26, ["param1"] = 2}, {["y"] = 1, ["x"] = 3, ["name"] = "default:stone", ["z"] = 27, ["param1"] = 2}, {["y"] = 1, ["x"] = 3, ["name"] = "default:stone", ["z"] = 28, ["param1"] = 2}, {["y"] = 1, ["x"] = 3, ["name"] = "default:stone", ["z"] = 29, ["param1"] = 2}, {["y"] = 1, ["x"] = 3, ["name"] = "default:stone", ["z"] = 30, ["param1"] = 2}, {["y"] = 1, ["x"] = 3, ["name"] = "default:stone", ["z"] = 31, ["param1"] = 2}, {["y"] = 2, ["x"] = 3, ["name"] = "default:stonebrick", ["z"] = 16, ["param2"] = 1, ["param1"] = 4}, {["y"] = 2, ["x"] = 3, ["name"] = "default:stonebrick", ["z"] = 17, ["param2"] = 1, ["param1"] = 4}, {["y"] = 2, ["x"] = 3, ["name"] = "default:stonebrick", ["z"] = 18, ["param2"] = 1, ["param1"] = 4}, {["y"] = 2, ["x"] = 3, ["name"] = "default:stonebrick", ["z"] = 19, ["param2"] = 1, ["param1"] = 4}, {["y"] = 2, ["x"] = 3, ["name"] = "default:stonebrick", ["z"] = 20, ["param2"] = 1, ["param1"] = 4}, {["y"] = 2, ["x"] = 3, ["name"] = "default:stonebrick", ["z"] = 21, ["param2"] = 1, ["param1"] = 4}, {["y"] = 2, ["x"] = 3, ["name"] = "default:stonebrick", ["z"] = 22, ["param2"] = 1, ["param1"] = 4}, {["y"] = 2, ["x"] = 3, ["name"] = "default:stonebrick", ["z"] = 23, ["param2"] = 1, ["param1"] = 4}, {["y"] = 2, ["x"] = 3, ["name"] = "default:stonebrick", ["z"] = 24, ["param2"] = 1, ["param1"] = 4}, {["y"] = 2, ["x"] = 3, ["name"] = "default:stonebrick", ["z"] = 25, ["param2"] = 1, ["param1"] = 4}, {["y"] = 2, ["x"] = 3, ["name"] = "default:stonebrick", ["z"] = 26, ["param2"] = 1, ["param1"] = 4}, {["y"] = 2, ["x"] = 3, ["name"] = "default:stonebrick", ["z"] = 27, ["param2"] = 1, ["param1"] = 4}, {["y"] = 2, ["x"] = 3, ["name"] = "default:stonebrick", ["z"] = 28, ["param2"] = 1, ["param1"] = 4}, {["y"] = 2, ["x"] = 3, ["name"] = "default:stonebrick", ["z"] = 29, ["param2"] = 1, ["param1"] = 4}, {["y"] = 2, ["x"] = 3, ["name"] = "default:stonebrick", ["z"] = 30, ["param2"] = 1, ["param1"] = 4}, {["y"] = 2, ["x"] = 3, ["name"] = "default:stonebrick", ["z"] = 31, ["param2"] = 1, ["param1"] = 4}, {["y"] = 3, ["x"] = 3, ["name"] = "moreblocks:checker_stone_tile", ["z"] = 16, ["param1"] = 46}, {["y"] = 3, ["x"] = 3, ["name"] = "moreblocks:checker_stone_tile", ["z"] = 17, ["param1"] = 46}, {["y"] = 3, ["x"] = 3, ["name"] = "moreblocks:checker_stone_tile", ["z"] = 18, ["param1"] = 46}, {["y"] = 3, ["x"] = 3, ["name"] = "moreblocks:checker_stone_tile", ["z"] = 19, ["param1"] = 46}, {["y"] = 3, ["x"] = 3, ["name"] = "moreblocks:checker_stone_tile", ["z"] = 20, ["param1"] = 46}, {["y"] = 3, ["x"] = 3, ["name"] = "moreblocks:checker_stone_tile", ["z"] = 21, ["param1"] = 46}, {["y"] = 3, ["x"] = 3, ["name"] = "moreblocks:checker_stone_tile", ["z"] = 22, ["param1"] = 46}, {["y"] = 3, ["x"] = 3, ["name"] = "moreblocks:checker_stone_tile", ["z"] = 23, ["param1"] = 46}, {["y"] = 3, ["x"] = 3, ["name"] = "moreblocks:checker_stone_tile", ["z"] = 24, ["param1"] = 46}, {["y"] = 3, ["x"] = 3, ["name"] = "moreblocks:checker_stone_tile", ["z"] = 25, ["param1"] = 46}, {["y"] = 3, ["x"] = 3, ["name"] = "moreblocks:checker_stone_tile", ["z"] = 26, ["param1"] = 46}, {["y"] = 3, ["x"] = 3, ["name"] = "moreblocks:checker_stone_tile", ["z"] = 27, ["param1"] = 46}, {["y"] = 3, ["x"] = 3, ["name"] = "moreblocks:checker_stone_tile", ["z"] = 28, ["param1"] = 46}, {["y"] = 3, ["x"] = 3, ["name"] = "moreblocks:checker_stone_tile", ["z"] = 29, ["param1"] = 46}, {["y"] = 3, ["x"] = 3, ["name"] = "moreblocks:checker_stone_tile", ["z"] = 30, ["param1"] = 46}, {["y"] = 3, ["x"] = 3, ["name"] = "moreblocks:checker_stone_tile", ["z"] = 31, ["param1"] = 46}, {["y"] = 7, ["x"] = 3, ["name"] = "moreblocks:coal_stone", ["z"] = 16, ["param1"] = 186}, {["y"] = 7, ["x"] = 3, ["name"] = "moreblocks:coal_stone", ["z"] = 17, ["param1"] = 186}, {["y"] = 7, ["x"] = 3, ["name"] = "moreblocks:coal_stone", ["z"] = 18, ["param1"] = 186}, {["y"] = 7, ["x"] = 3, ["name"] = "moreblocks:coal_stone", ["z"] = 19, ["param1"] = 186}, {["y"] = 7, ["x"] = 3, ["name"] = "moreblocks:coal_stone", ["z"] = 20, ["param1"] = 186}, {["y"] = 7, ["x"] = 3, ["name"] = "moreblocks:coal_stone", ["z"] = 21, ["param1"] = 186}, {["y"] = 7, ["x"] = 3, ["name"] = "moreblocks:coal_stone", ["z"] = 22, ["param1"] = 186}, {["y"] = 7, ["x"] = 3, ["name"] = "moreblocks:coal_stone", ["z"] = 23, ["param1"] = 186}, {["y"] = 7, ["x"] = 3, ["name"] = "moreblocks:coal_stone", ["z"] = 24, ["param1"] = 186}, {["y"] = 7, ["x"] = 3, ["name"] = "moreblocks:coal_stone", ["z"] = 25, ["param1"] = 186}, {["y"] = 7, ["x"] = 3, ["name"] = "moreblocks:coal_stone", ["z"] = 26, ["param1"] = 186}, {["y"] = 7, ["x"] = 3, ["name"] = "moreblocks:coal_stone", ["z"] = 27, ["param1"] = 186}, {["y"] = 7, ["x"] = 3, ["name"] = "moreblocks:coal_stone", ["z"] = 28, ["param1"] = 186}, {["y"] = 7, ["x"] = 3, ["name"] = "moreblocks:coal_stone", ["z"] = 29, ["param1"] = 186}, {["y"] = 7, ["x"] = 3, ["name"] = "moreblocks:coal_stone", ["z"] = 30, ["param1"] = 186}, {["y"] = 7, ["x"] = 3, ["name"] = "moreblocks:coal_stone", ["z"] = 31, ["param1"] = 186}, {["y"] = 8, ["x"] = 3, ["name"] = "moreblocks:checker_stone_tile", ["z"] = 16, ["param1"] = 46}, {["y"] = 8, ["x"] = 3, ["name"] = "moreblocks:checker_stone_tile", ["z"] = 17, ["param1"] = 46}, {["y"] = 8, ["x"] = 3, ["name"] = "moreblocks:checker_stone_tile", ["z"] = 18, ["param1"] = 46}, {["y"] = 8, ["x"] = 3, ["name"] = "moreblocks:checker_stone_tile", ["z"] = 19, ["param1"] = 46}, {["y"] = 8, ["x"] = 3, ["name"] = "moreblocks:checker_stone_tile", ["z"] = 20, ["param1"] = 46}, {["y"] = 8, ["x"] = 3, ["name"] = "moreblocks:checker_stone_tile", ["z"] = 21, ["param1"] = 46}, {["y"] = 8, ["x"] = 3, ["name"] = "moreblocks:checker_stone_tile", ["z"] = 22, ["param1"] = 46}, {["y"] = 8, ["x"] = 3, ["name"] = "moreblocks:checker_stone_tile", ["z"] = 23, ["param1"] = 46}, {["y"] = 8, ["x"] = 3, ["name"] = "moreblocks:checker_stone_tile", ["z"] = 24, ["param1"] = 46}, {["y"] = 8, ["x"] = 3, ["name"] = "moreblocks:checker_stone_tile", ["z"] = 25, ["param1"] = 46}, {["y"] = 8, ["x"] = 3, ["name"] = "moreblocks:checker_stone_tile", ["z"] = 26, ["param1"] = 46}, {["y"] = 8, ["x"] = 3, ["name"] = "moreblocks:checker_stone_tile", ["z"] = 27, ["param1"] = 46}, {["y"] = 8, ["x"] = 3, ["name"] = "moreblocks:checker_stone_tile", ["z"] = 28, ["param1"] = 46}, {["y"] = 8, ["x"] = 3, ["name"] = "moreblocks:checker_stone_tile", ["z"] = 29, ["param1"] = 46}, {["y"] = 8, ["x"] = 3, ["name"] = "moreblocks:checker_stone_tile", ["z"] = 30, ["param1"] = 46}, {["y"] = 8, ["x"] = 3, ["name"] = "moreblocks:checker_stone_tile", ["z"] = 31, ["param1"] = 46}, {["y"] = 15, ["x"] = 3, ["name"] = "moreblocks:coal_stone", ["z"] = 16, ["param1"] = 186}, {["y"] = 15, ["x"] = 3, ["name"] = "moreblocks:coal_stone", ["z"] = 17, ["param1"] = 186}, {["y"] = 15, ["x"] = 3, ["name"] = "moreblocks:coal_stone", ["z"] = 18, ["param1"] = 186}, {["y"] = 15, ["x"] = 3, ["name"] = "moreblocks:coal_stone", ["z"] = 19, ["param1"] = 186}, {["y"] = 15, ["x"] = 3, ["name"] = "moreblocks:coal_stone", ["z"] = 20, ["param1"] = 186}, {["y"] = 15, ["x"] = 3, ["name"] = "moreblocks:coal_stone", ["z"] = 21, ["param1"] = 186}, {["y"] = 15, ["x"] = 3, ["name"] = "moreblocks:coal_stone", ["z"] = 22, ["param1"] = 186}, {["y"] = 15, ["x"] = 3, ["name"] = "moreblocks:coal_stone", ["z"] = 23, ["param1"] = 186}, {["y"] = 15, ["x"] = 3, ["name"] = "moreblocks:coal_stone", ["z"] = 24, ["param1"] = 186}, {["y"] = 15, ["x"] = 3, ["name"] = "moreblocks:coal_stone", ["z"] = 25, ["param1"] = 186}, {["y"] = 15, ["x"] = 3, ["name"] = "moreblocks:coal_stone", ["z"] = 26, ["param1"] = 186}, {["y"] = 15, ["x"] = 3, ["name"] = "moreblocks:coal_stone", ["z"] = 27, ["param1"] = 186}, {["y"] = 15, ["x"] = 3, ["name"] = "moreblocks:coal_stone", ["z"] = 28, ["param1"] = 186}, {["y"] = 15, ["x"] = 3, ["name"] = "moreblocks:coal_stone", ["z"] = 29, ["param1"] = 186}, {["y"] = 15, ["x"] = 3, ["name"] = "moreblocks:coal_stone", ["z"] = 30, ["param1"] = 186}, {["y"] = 15, ["x"] = 3, ["name"] = "moreblocks:coal_stone", ["z"] = 31, ["param1"] = 186}, {["y"] = 16, ["x"] = 3, ["name"] = "moreblocks:checker_stone_tile", ["z"] = 16, ["param1"] = 46}, {["y"] = 16, ["x"] = 3, ["name"] = "moreblocks:checker_stone_tile", ["z"] = 17, ["param1"] = 46}, {["y"] = 16, ["x"] = 3, ["name"] = "moreblocks:checker_stone_tile", ["z"] = 18, ["param1"] = 46}, {["y"] = 16, ["x"] = 3, ["name"] = "moreblocks:checker_stone_tile", ["z"] = 19, ["param1"] = 46}, {["y"] = 16, ["x"] = 3, ["name"] = "moreblocks:checker_stone_tile", ["z"] = 20, ["param1"] = 46}, {["y"] = 16, ["x"] = 3, ["name"] = "moreblocks:checker_stone_tile", ["z"] = 21, ["param1"] = 46}, {["y"] = 16, ["x"] = 3, ["name"] = "moreblocks:checker_stone_tile", ["z"] = 22, ["param1"] = 46}, {["y"] = 16, ["x"] = 3, ["name"] = "moreblocks:checker_stone_tile", ["z"] = 23, ["param1"] = 46}, {["y"] = 16, ["x"] = 3, ["name"] = "moreblocks:checker_stone_tile", ["z"] = 24, ["param1"] = 46}, {["y"] = 16, ["x"] = 3, ["name"] = "moreblocks:checker_stone_tile", ["z"] = 25, ["param1"] = 46}, {["y"] = 16, ["x"] = 3, ["name"] = "moreblocks:checker_stone_tile", ["z"] = 26, ["param1"] = 46}, {["y"] = 16, ["x"] = 3, ["name"] = "moreblocks:checker_stone_tile", ["z"] = 27, ["param1"] = 46}, {["y"] = 16, ["x"] = 3, ["name"] = "moreblocks:checker_stone_tile", ["z"] = 28, ["param1"] = 46}, {["y"] = 16, ["x"] = 3, ["name"] = "moreblocks:checker_stone_tile", ["z"] = 29, ["param1"] = 46}, {["y"] = 16, ["x"] = 3, ["name"] = "moreblocks:checker_stone_tile", ["z"] = 30, ["param1"] = 46}, {["y"] = 16, ["x"] = 3, ["name"] = "moreblocks:checker_stone_tile", ["z"] = 31, ["param1"] = 46}, {["y"] = 23, ["x"] = 3, ["name"] = "moreblocks:coal_stone", ["z"] = 16, ["param1"] = 186}, {["y"] = 23, ["x"] = 3, ["name"] = "moreblocks:coal_stone", ["z"] = 17, ["param1"] = 186}, {["y"] = 23, ["x"] = 3, ["name"] = "moreblocks:coal_stone", ["z"] = 18, ["param1"] = 186}, {["y"] = 23, ["x"] = 3, ["name"] = "moreblocks:coal_stone", ["z"] = 19, ["param1"] = 186}, {["y"] = 23, ["x"] = 3, ["name"] = "moreblocks:coal_stone", ["z"] = 20, ["param1"] = 186}, {["y"] = 23, ["x"] = 3, ["name"] = "moreblocks:coal_stone", ["z"] = 21, ["param1"] = 186}, {["y"] = 23, ["x"] = 3, ["name"] = "moreblocks:coal_stone", ["z"] = 22, ["param1"] = 186}, {["y"] = 23, ["x"] = 3, ["name"] = "moreblocks:coal_stone", ["z"] = 23, ["param1"] = 186}, {["y"] = 23, ["x"] = 3, ["name"] = "moreblocks:coal_stone", ["z"] = 24, ["param1"] = 186}, {["y"] = 23, ["x"] = 3, ["name"] = "moreblocks:coal_stone", ["z"] = 25, ["param1"] = 186}, {["y"] = 23, ["x"] = 3, ["name"] = "moreblocks:coal_stone", ["z"] = 26, ["param1"] = 186}, {["y"] = 23, ["x"] = 3, ["name"] = "moreblocks:coal_stone", ["z"] = 27, ["param1"] = 186}, {["y"] = 23, ["x"] = 3, ["name"] = "moreblocks:coal_stone", ["z"] = 28, ["param1"] = 186}, {["y"] = 23, ["x"] = 3, ["name"] = "moreblocks:coal_stone", ["z"] = 29, ["param1"] = 186}, {["y"] = 23, ["x"] = 3, ["name"] = "moreblocks:coal_stone", ["z"] = 30, ["param1"] = 186}, {["y"] = 23, ["x"] = 3, ["name"] = "moreblocks:coal_stone", ["z"] = 31, ["param1"] = 186}, {["y"] = 24, ["x"] = 3, ["name"] = "moreblocks:checker_stone_tile", ["z"] = 16, ["param1"] = 46}, {["y"] = 24, ["x"] = 3, ["name"] = "moreblocks:checker_stone_tile", ["z"] = 17, ["param1"] = 46}, {["y"] = 24, ["x"] = 3, ["name"] = "moreblocks:checker_stone_tile", ["z"] = 18, ["param1"] = 46}, {["y"] = 24, ["x"] = 3, ["name"] = "moreblocks:checker_stone_tile", ["z"] = 19, ["param1"] = 46}, {["y"] = 24, ["x"] = 3, ["name"] = "moreblocks:checker_stone_tile", ["z"] = 20, ["param1"] = 46}, {["y"] = 24, ["x"] = 3, ["name"] = "moreblocks:checker_stone_tile", ["z"] = 21, ["param1"] = 46}, {["y"] = 24, ["x"] = 3, ["name"] = "moreblocks:checker_stone_tile", ["z"] = 22, ["param1"] = 46}, {["y"] = 24, ["x"] = 3, ["name"] = "moreblocks:checker_stone_tile", ["z"] = 23, ["param1"] = 46}, {["y"] = 24, ["x"] = 3, ["name"] = "moreblocks:checker_stone_tile", ["z"] = 24, ["param1"] = 46}, {["y"] = 24, ["x"] = 3, ["name"] = "moreblocks:checker_stone_tile", ["z"] = 25, ["param1"] = 46}, {["y"] = 24, ["x"] = 3, ["name"] = "moreblocks:checker_stone_tile", ["z"] = 26, ["param1"] = 46}, {["y"] = 24, ["x"] = 3, ["name"] = "moreblocks:checker_stone_tile", ["z"] = 27, ["param1"] = 46}, {["y"] = 24, ["x"] = 3, ["name"] = "moreblocks:checker_stone_tile", ["z"] = 28, ["param1"] = 46}, {["y"] = 24, ["x"] = 3, ["name"] = "moreblocks:checker_stone_tile", ["z"] = 29, ["param1"] = 46}, {["y"] = 24, ["x"] = 3, ["name"] = "moreblocks:checker_stone_tile", ["z"] = 30, ["param1"] = 46}, {["y"] = 24, ["x"] = 3, ["name"] = "moreblocks:checker_stone_tile", ["z"] = 31, ["param1"] = 46}, {["y"] = 31, ["x"] = 3, ["name"] = "moreblocks:coal_stone", ["z"] = 16, ["param1"] = 186}, {["y"] = 31, ["x"] = 3, ["name"] = "moreblocks:coal_stone", ["z"] = 17, ["param1"] = 186}, {["y"] = 31, ["x"] = 3, ["name"] = "moreblocks:coal_stone", ["z"] = 18, ["param1"] = 186}, {["y"] = 31, ["x"] = 3, ["name"] = "moreblocks:coal_stone", ["z"] = 19, ["param1"] = 186}, {["y"] = 31, ["x"] = 3, ["name"] = "moreblocks:coal_stone", ["z"] = 20, ["param1"] = 186}, {["y"] = 31, ["x"] = 3, ["name"] = "moreblocks:coal_stone", ["z"] = 21, ["param1"] = 186}, {["y"] = 31, ["x"] = 3, ["name"] = "moreblocks:coal_stone", ["z"] = 22, ["param1"] = 186}, {["y"] = 31, ["x"] = 3, ["name"] = "moreblocks:coal_stone", ["z"] = 23, ["param1"] = 186}, {["y"] = 31, ["x"] = 3, ["name"] = "moreblocks:coal_stone", ["z"] = 24, ["param1"] = 186}, {["y"] = 31, ["x"] = 3, ["name"] = "moreblocks:coal_stone", ["z"] = 25, ["param1"] = 186}, {["y"] = 31, ["x"] = 3, ["name"] = "moreblocks:coal_stone", ["z"] = 26, ["param1"] = 186}, {["y"] = 31, ["x"] = 3, ["name"] = "moreblocks:coal_stone", ["z"] = 27, ["param1"] = 186}, {["y"] = 31, ["x"] = 3, ["name"] = "moreblocks:coal_stone", ["z"] = 28, ["param1"] = 186}, {["y"] = 31, ["x"] = 3, ["name"] = "moreblocks:coal_stone", ["z"] = 29, ["param1"] = 186}, {["y"] = 31, ["x"] = 3, ["name"] = "moreblocks:coal_stone", ["z"] = 30, ["param1"] = 186}, {["y"] = 31, ["x"] = 3, ["name"] = "moreblocks:coal_stone", ["z"] = 31, ["param1"] = 186}, {["y"] = 32, ["x"] = 3, ["name"] = "moreblocks:checker_stone_tile", ["z"] = 16, ["param1"] = 46}, {["y"] = 32, ["x"] = 3, ["name"] = "moreblocks:checker_stone_tile", ["z"] = 17, ["param1"] = 46}, {["y"] = 32, ["x"] = 3, ["name"] = "moreblocks:checker_stone_tile", ["z"] = 18, ["param1"] = 46}, {["y"] = 32, ["x"] = 3, ["name"] = "moreblocks:checker_stone_tile", ["z"] = 19, ["param1"] = 46}, {["y"] = 32, ["x"] = 3, ["name"] = "moreblocks:checker_stone_tile", ["z"] = 20, ["param1"] = 46}, {["y"] = 32, ["x"] = 3, ["name"] = "moreblocks:checker_stone_tile", ["z"] = 21, ["param1"] = 46}, {["y"] = 32, ["x"] = 3, ["name"] = "moreblocks:checker_stone_tile", ["z"] = 22, ["param1"] = 46}, {["y"] = 32, ["x"] = 3, ["name"] = "moreblocks:checker_stone_tile", ["z"] = 23, ["param1"] = 46}, {["y"] = 32, ["x"] = 3, ["name"] = "moreblocks:checker_stone_tile", ["z"] = 24, ["param1"] = 46}, {["y"] = 32, ["x"] = 3, ["name"] = "moreblocks:checker_stone_tile", ["z"] = 25, ["param1"] = 46}, {["y"] = 32, ["x"] = 3, ["name"] = "moreblocks:checker_stone_tile", ["z"] = 26, ["param1"] = 46}, {["y"] = 32, ["x"] = 3, ["name"] = "moreblocks:checker_stone_tile", ["z"] = 27, ["param1"] = 46}, {["y"] = 32, ["x"] = 3, ["name"] = "moreblocks:checker_stone_tile", ["z"] = 28, ["param1"] = 46}, {["y"] = 32, ["x"] = 3, ["name"] = "moreblocks:checker_stone_tile", ["z"] = 29, ["param1"] = 46}, {["y"] = 32, ["x"] = 3, ["name"] = "moreblocks:checker_stone_tile", ["z"] = 30, ["param1"] = 46}, {["y"] = 32, ["x"] = 3, ["name"] = "moreblocks:checker_stone_tile", ["z"] = 31, ["param1"] = 46}, {["y"] = 39, ["x"] = 3, ["name"] = "moreblocks:coal_stone", ["z"] = 16, ["param1"] = 186}, {["y"] = 39, ["x"] = 3, ["name"] = "moreblocks:coal_stone", ["z"] = 17, ["param1"] = 186}, {["y"] = 39, ["x"] = 3, ["name"] = "moreblocks:coal_stone", ["z"] = 18, ["param1"] = 186}, {["y"] = 39, ["x"] = 3, ["name"] = "moreblocks:coal_stone", ["z"] = 19, ["param1"] = 186}, {["y"] = 39, ["x"] = 3, ["name"] = "moreblocks:coal_stone", ["z"] = 20, ["param1"] = 186}, {["y"] = 39, ["x"] = 3, ["name"] = "moreblocks:coal_stone", ["z"] = 21, ["param1"] = 186}, {["y"] = 39, ["x"] = 3, ["name"] = "moreblocks:coal_stone", ["z"] = 22, ["param1"] = 186}, {["y"] = 39, ["x"] = 3, ["name"] = "moreblocks:coal_stone", ["z"] = 23, ["param1"] = 186}, {["y"] = 39, ["x"] = 3, ["name"] = "moreblocks:coal_stone", ["z"] = 24, ["param1"] = 186}, {["y"] = 39, ["x"] = 3, ["name"] = "moreblocks:coal_stone", ["z"] = 25, ["param1"] = 186}, {["y"] = 39, ["x"] = 3, ["name"] = "moreblocks:coal_stone", ["z"] = 26, ["param1"] = 186}, {["y"] = 39, ["x"] = 3, ["name"] = "moreblocks:coal_stone", ["z"] = 27, ["param1"] = 186}, {["y"] = 39, ["x"] = 3, ["name"] = "moreblocks:coal_stone", ["z"] = 28, ["param1"] = 186}, {["y"] = 39, ["x"] = 3, ["name"] = "moreblocks:coal_stone", ["z"] = 29, ["param1"] = 186}, {["y"] = 39, ["x"] = 3, ["name"] = "moreblocks:coal_stone", ["z"] = 30, ["param1"] = 186}, {["y"] = 39, ["x"] = 3, ["name"] = "moreblocks:coal_stone", ["z"] = 31, ["param1"] = 186}, {["y"] = 40, ["x"] = 3, ["name"] = "moreblocks:checker_stone_tile", ["z"] = 16, ["param1"] = 46}, {["y"] = 40, ["x"] = 3, ["name"] = "moreblocks:checker_stone_tile", ["z"] = 17, ["param1"] = 46}, {["y"] = 40, ["x"] = 3, ["name"] = "moreblocks:checker_stone_tile", ["z"] = 18, ["param1"] = 46}, {["y"] = 40, ["x"] = 3, ["name"] = "moreblocks:checker_stone_tile", ["z"] = 19, ["param1"] = 46}, {["y"] = 40, ["x"] = 3, ["name"] = "moreblocks:checker_stone_tile", ["z"] = 20, ["param1"] = 46}, {["y"] = 40, ["x"] = 3, ["name"] = "moreblocks:checker_stone_tile", ["z"] = 21, ["param1"] = 46}, {["y"] = 40, ["x"] = 3, ["name"] = "moreblocks:checker_stone_tile", ["z"] = 22, ["param1"] = 46}, {["y"] = 40, ["x"] = 3, ["name"] = "moreblocks:checker_stone_tile", ["z"] = 23, ["param1"] = 46}, {["y"] = 40, ["x"] = 3, ["name"] = "moreblocks:checker_stone_tile", ["z"] = 24, ["param1"] = 46}, {["y"] = 40, ["x"] = 3, ["name"] = "moreblocks:checker_stone_tile", ["z"] = 25, ["param1"] = 46}, {["y"] = 40, ["x"] = 3, ["name"] = "moreblocks:checker_stone_tile", ["z"] = 26, ["param1"] = 46}, {["y"] = 40, ["x"] = 3, ["name"] = "moreblocks:checker_stone_tile", ["z"] = 27, ["param1"] = 46}, {["y"] = 40, ["x"] = 3, ["name"] = "moreblocks:checker_stone_tile", ["z"] = 28, ["param1"] = 46}, {["y"] = 40, ["x"] = 3, ["name"] = "moreblocks:checker_stone_tile", ["z"] = 29, ["param1"] = 46}, {["y"] = 40, ["x"] = 3, ["name"] = "moreblocks:checker_stone_tile", ["z"] = 30, ["param1"] = 46}, {["y"] = 40, ["x"] = 3, ["name"] = "moreblocks:checker_stone_tile", ["z"] = 31, ["param1"] = 46}, {["y"] = 47, ["x"] = 3, ["name"] = "moreblocks:coal_stone", ["z"] = 16, ["param1"] = 186}, {["y"] = 47, ["x"] = 3, ["name"] = "moreblocks:coal_stone", ["z"] = 17, ["param1"] = 186}, {["y"] = 47, ["x"] = 3, ["name"] = "moreblocks:coal_stone", ["z"] = 18, ["param1"] = 186}, {["y"] = 47, ["x"] = 3, ["name"] = "moreblocks:coal_stone", ["z"] = 19, ["param1"] = 186}, {["y"] = 47, ["x"] = 3, ["name"] = "moreblocks:coal_stone", ["z"] = 20, ["param1"] = 186}, {["y"] = 47, ["x"] = 3, ["name"] = "moreblocks:coal_stone", ["z"] = 21, ["param1"] = 186}, {["y"] = 47, ["x"] = 3, ["name"] = "moreblocks:coal_stone", ["z"] = 22, ["param1"] = 186}, {["y"] = 47, ["x"] = 3, ["name"] = "moreblocks:coal_stone", ["z"] = 23, ["param1"] = 186}, {["y"] = 47, ["x"] = 3, ["name"] = "moreblocks:coal_stone", ["z"] = 24, ["param1"] = 186}, {["y"] = 47, ["x"] = 3, ["name"] = "moreblocks:coal_stone", ["z"] = 25, ["param1"] = 186}, {["y"] = 47, ["x"] = 3, ["name"] = "moreblocks:coal_stone", ["z"] = 26, ["param1"] = 186}, {["y"] = 47, ["x"] = 3, ["name"] = "moreblocks:coal_stone", ["z"] = 27, ["param1"] = 186}, {["y"] = 47, ["x"] = 3, ["name"] = "moreblocks:coal_stone", ["z"] = 28, ["param1"] = 186}, {["y"] = 47, ["x"] = 3, ["name"] = "moreblocks:coal_stone", ["z"] = 29, ["param1"] = 186}, {["y"] = 47, ["x"] = 3, ["name"] = "moreblocks:coal_stone", ["z"] = 30, ["param1"] = 186}, {["y"] = 47, ["x"] = 3, ["name"] = "moreblocks:coal_stone", ["z"] = 31, ["param1"] = 186}, {["y"] = 0, ["x"] = 4, ["name"] = "default:stone", ["z"] = 16, ["param1"] = 2}, {["y"] = 0, ["x"] = 4, ["name"] = "default:stone", ["z"] = 17, ["param1"] = 2}, {["y"] = 0, ["x"] = 4, ["name"] = "default:stone", ["z"] = 18, ["param1"] = 2}, {["y"] = 0, ["x"] = 4, ["name"] = "default:stone", ["z"] = 19, ["param1"] = 2}, {["y"] = 0, ["x"] = 4, ["name"] = "default:stone", ["z"] = 20, ["param1"] = 2}, {["y"] = 0, ["x"] = 4, ["name"] = "default:stone", ["z"] = 21, ["param1"] = 2}, {["y"] = 0, ["x"] = 4, ["name"] = "default:stone", ["z"] = 22, ["param1"] = 2}, {["y"] = 0, ["x"] = 4, ["name"] = "default:stone", ["z"] = 23, ["param1"] = 2}, {["y"] = 0, ["x"] = 4, ["name"] = "default:stone", ["z"] = 24, ["param1"] = 2}, {["y"] = 0, ["x"] = 4, ["name"] = "default:stone", ["z"] = 25, ["param1"] = 2}, {["y"] = 0, ["x"] = 4, ["name"] = "default:stone", ["z"] = 26, ["param1"] = 2}, {["y"] = 0, ["x"] = 4, ["name"] = "default:stone", ["z"] = 27, ["param1"] = 2}, {["y"] = 0, ["x"] = 4, ["name"] = "default:stone", ["z"] = 28, ["param1"] = 2}, {["y"] = 0, ["x"] = 4, ["name"] = "default:stone", ["z"] = 29, ["param1"] = 2}, {["y"] = 0, ["x"] = 4, ["name"] = "default:stone", ["z"] = 30, ["param1"] = 2}, {["y"] = 0, ["x"] = 4, ["name"] = "default:stone", ["z"] = 31, ["param1"] = 2}, {["y"] = 1, ["x"] = 4, ["name"] = "default:stone", ["z"] = 16, ["param1"] = 2}, {["y"] = 1, ["x"] = 4, ["name"] = "default:stone", ["z"] = 17, ["param1"] = 2}, {["y"] = 1, ["x"] = 4, ["name"] = "default:stone", ["z"] = 18, ["param1"] = 2}, {["y"] = 1, ["x"] = 4, ["name"] = "default:stone", ["z"] = 19, ["param1"] = 2}, {["y"] = 1, ["x"] = 4, ["name"] = "default:stone", ["z"] = 20, ["param1"] = 2}, {["y"] = 1, ["x"] = 4, ["name"] = "default:stone", ["z"] = 21, ["param1"] = 2}, {["y"] = 1, ["x"] = 4, ["name"] = "default:stone", ["z"] = 22, ["param1"] = 2}, {["y"] = 1, ["x"] = 4, ["name"] = "default:stone", ["z"] = 23, ["param1"] = 2}, {["y"] = 1, ["x"] = 4, ["name"] = "default:stone", ["z"] = 24, ["param1"] = 2}, {["y"] = 1, ["x"] = 4, ["name"] = "default:stone", ["z"] = 25, ["param1"] = 2}, {["y"] = 1, ["x"] = 4, ["name"] = "default:stone", ["z"] = 26, ["param1"] = 2}, {["y"] = 1, ["x"] = 4, ["name"] = "default:stone", ["z"] = 27, ["param1"] = 2}, {["y"] = 1, ["x"] = 4, ["name"] = "default:stone", ["z"] = 28, ["param1"] = 2}, {["y"] = 1, ["x"] = 4, ["name"] = "default:stone", ["z"] = 29, ["param1"] = 2}, {["y"] = 1, ["x"] = 4, ["name"] = "default:stone", ["z"] = 30, ["param1"] = 2}, {["y"] = 1, ["x"] = 4, ["name"] = "default:stone", ["z"] = 31, ["param1"] = 2}, {["y"] = 2, ["x"] = 4, ["name"] = "default:stonebrick", ["z"] = 16, ["param2"] = 1, ["param1"] = 4}, {["y"] = 2, ["x"] = 4, ["name"] = "default:stonebrick", ["z"] = 17, ["param2"] = 1, ["param1"] = 4}, {["y"] = 2, ["x"] = 4, ["name"] = "default:stonebrick", ["z"] = 18, ["param2"] = 1, ["param1"] = 4}, {["y"] = 2, ["x"] = 4, ["name"] = "default:stonebrick", ["z"] = 19, ["param2"] = 1, ["param1"] = 4}, {["y"] = 2, ["x"] = 4, ["name"] = "default:stonebrick", ["z"] = 20, ["param2"] = 1, ["param1"] = 4}, {["y"] = 2, ["x"] = 4, ["name"] = "default:stonebrick", ["z"] = 21, ["param2"] = 1, ["param1"] = 4}, {["y"] = 2, ["x"] = 4, ["name"] = "default:stonebrick", ["z"] = 22, ["param2"] = 1, ["param1"] = 4}, {["y"] = 2, ["x"] = 4, ["name"] = "default:stonebrick", ["z"] = 23, ["param2"] = 1, ["param1"] = 4}, {["y"] = 2, ["x"] = 4, ["name"] = "default:stonebrick", ["z"] = 24, ["param2"] = 1, ["param1"] = 4}, {["y"] = 2, ["x"] = 4, ["name"] = "default:stonebrick", ["z"] = 25, ["param2"] = 1, ["param1"] = 4}, {["y"] = 2, ["x"] = 4, ["name"] = "default:stonebrick", ["z"] = 26, ["param2"] = 1, ["param1"] = 4}, {["y"] = 2, ["x"] = 4, ["name"] = "default:stonebrick", ["z"] = 27, ["param2"] = 1, ["param1"] = 4}, {["y"] = 2, ["x"] = 4, ["name"] = "default:stonebrick", ["z"] = 28, ["param2"] = 1, ["param1"] = 4}, {["y"] = 2, ["x"] = 4, ["name"] = "default:stonebrick", ["z"] = 29, ["param2"] = 1, ["param1"] = 4}, {["y"] = 2, ["x"] = 4, ["name"] = "default:stonebrick", ["z"] = 30, ["param2"] = 1, ["param1"] = 4}, {["y"] = 2, ["x"] = 4, ["name"] = "default:stonebrick", ["z"] = 31, ["param2"] = 1, ["param1"] = 4}, {["y"] = 3, ["x"] = 4, ["name"] = "moreblocks:checker_stone_tile", ["z"] = 16, ["param1"] = 46}, {["y"] = 3, ["x"] = 4, ["name"] = "moreblocks:checker_stone_tile", ["z"] = 17, ["param1"] = 46}, {["y"] = 3, ["x"] = 4, ["name"] = "moreblocks:checker_stone_tile", ["z"] = 18, ["param1"] = 46}, {["y"] = 3, ["x"] = 4, ["name"] = "moreblocks:checker_stone_tile", ["z"] = 19, ["param1"] = 46}, {["y"] = 3, ["x"] = 4, ["name"] = "moreblocks:checker_stone_tile", ["z"] = 20, ["param1"] = 46}, {["y"] = 3, ["x"] = 4, ["name"] = "moreblocks:checker_stone_tile", ["z"] = 21, ["param1"] = 46}, {["y"] = 3, ["x"] = 4, ["name"] = "moreblocks:checker_stone_tile", ["z"] = 22, ["param1"] = 46}, {["y"] = 3, ["x"] = 4, ["name"] = "moreblocks:checker_stone_tile", ["z"] = 23, ["param1"] = 46}, {["y"] = 3, ["x"] = 4, ["name"] = "moreblocks:checker_stone_tile", ["z"] = 24, ["param1"] = 46}, {["y"] = 3, ["x"] = 4, ["name"] = "moreblocks:checker_stone_tile", ["z"] = 25, ["param1"] = 46}, {["y"] = 3, ["x"] = 4, ["name"] = "moreblocks:checker_stone_tile", ["z"] = 26, ["param1"] = 46}, {["y"] = 3, ["x"] = 4, ["name"] = "moreblocks:checker_stone_tile", ["z"] = 27, ["param1"] = 46}, {["y"] = 3, ["x"] = 4, ["name"] = "moreblocks:checker_stone_tile", ["z"] = 28, ["param1"] = 46}, {["y"] = 3, ["x"] = 4, ["name"] = "moreblocks:checker_stone_tile", ["z"] = 29, ["param1"] = 46}, {["y"] = 3, ["x"] = 4, ["name"] = "moreblocks:checker_stone_tile", ["z"] = 30, ["param1"] = 46}, {["y"] = 3, ["x"] = 4, ["name"] = "moreblocks:checker_stone_tile", ["z"] = 31, ["param1"] = 46}, {["y"] = 7, ["x"] = 4, ["name"] = "moreblocks:coal_stone", ["z"] = 16, ["param1"] = 186}, {["y"] = 7, ["x"] = 4, ["name"] = "moreblocks:coal_stone", ["z"] = 17, ["param1"] = 186}, {["y"] = 7, ["x"] = 4, ["name"] = "moreblocks:coal_stone", ["z"] = 18, ["param1"] = 186}, {["y"] = 7, ["x"] = 4, ["name"] = "moreblocks:coal_stone", ["z"] = 19, ["param1"] = 186}, {["y"] = 7, ["x"] = 4, ["name"] = "moreblocks:coal_stone", ["z"] = 20, ["param1"] = 186}, {["y"] = 7, ["x"] = 4, ["name"] = "moreblocks:coal_stone", ["z"] = 21, ["param1"] = 186}, {["y"] = 7, ["x"] = 4, ["name"] = "moreblocks:coal_stone", ["z"] = 22, ["param1"] = 186}, {["y"] = 7, ["x"] = 4, ["name"] = "moreblocks:coal_stone", ["z"] = 23, ["param1"] = 186}, {["y"] = 7, ["x"] = 4, ["name"] = "moreblocks:coal_stone", ["z"] = 24, ["param1"] = 186}, {["y"] = 7, ["x"] = 4, ["name"] = "moreblocks:coal_stone", ["z"] = 25, ["param1"] = 186}, {["y"] = 7, ["x"] = 4, ["name"] = "moreblocks:coal_stone", ["z"] = 26, ["param1"] = 186}, {["y"] = 7, ["x"] = 4, ["name"] = "moreblocks:coal_stone", ["z"] = 27, ["param1"] = 186}, {["y"] = 7, ["x"] = 4, ["name"] = "moreblocks:coal_stone", ["z"] = 28, ["param1"] = 186}, {["y"] = 7, ["x"] = 4, ["name"] = "moreblocks:coal_stone", ["z"] = 29, ["param1"] = 186}, {["y"] = 7, ["x"] = 4, ["name"] = "moreblocks:coal_stone", ["z"] = 30, ["param1"] = 186}, {["y"] = 7, ["x"] = 4, ["name"] = "moreblocks:coal_stone", ["z"] = 31, ["param1"] = 186}, {["y"] = 8, ["x"] = 4, ["name"] = "moreblocks:checker_stone_tile", ["z"] = 16, ["param1"] = 46}, {["y"] = 8, ["x"] = 4, ["name"] = "moreblocks:checker_stone_tile", ["z"] = 17, ["param1"] = 46}, {["y"] = 8, ["x"] = 4, ["name"] = "moreblocks:checker_stone_tile", ["z"] = 18, ["param1"] = 46}, {["y"] = 8, ["x"] = 4, ["name"] = "moreblocks:checker_stone_tile", ["z"] = 19, ["param1"] = 46}, {["y"] = 8, ["x"] = 4, ["name"] = "moreblocks:checker_stone_tile", ["z"] = 20, ["param1"] = 46}, {["y"] = 8, ["x"] = 4, ["name"] = "moreblocks:checker_stone_tile", ["z"] = 21, ["param1"] = 46}, {["y"] = 8, ["x"] = 4, ["name"] = "moreblocks:checker_stone_tile", ["z"] = 22, ["param1"] = 46}, {["y"] = 8, ["x"] = 4, ["name"] = "moreblocks:checker_stone_tile", ["z"] = 23, ["param1"] = 46}, {["y"] = 8, ["x"] = 4, ["name"] = "moreblocks:checker_stone_tile", ["z"] = 24, ["param1"] = 46}, {["y"] = 8, ["x"] = 4, ["name"] = "moreblocks:checker_stone_tile", ["z"] = 25, ["param1"] = 46},